Workbook

Sheet Карта
A1: Story map продукта Stud Book
A2: Версия 1.0. Роли: клиент; сотрудник ранчо (представления «Владелец» и «Финансы»). На каждой карточке: номер истории, основной пакет ИСР, название. Подробности — на листе «Истории».
A3: Обозначения: | B3: Must | C3: Should | D3: Could | E3: Пунктир: пакет исключён в варианте Б базового плана
A5: Клиент (владелец кобылы, в том числе удалённый)
A6: Этапы пути пользователя | B6: Подать заявку | C6: Заказать семя | D6: Следить за заявкой | E6: Получить и оплатить счёт
A7: Хорошо бы сделать (Should) | B7: CL-01 ИСР 5.1 Подать заявку на случку | C7: CL-03 ИСР 5.2 Заказать семя с доставкой вариант Б: исключён | D7: CL-05 ИСР 5.1 Видеть статус заявки | E7: CL-08 ИСР 5.3 Видеть счета и статус оплаты вариант Б: исключён
B8: CL-02 ИСР 5.1 Указать кобылу, жеребца и период | C8: CL-04 ИСР 5.2 Адрес и статус доставки семени вариант Б: исключён | D8: CL-06 ИСР 5.1 Видеть историю заявок | E8: CL-09 ИСР 5.3 Оплатить счёт (заглушка) вариант Б: исключён
A9: Можно будет сделать (Could) | D9: CL-07 ИСР 6.1 Уведомление о статусе (заглушка)
A11: Сотрудник ранчо, представление «Владелец» (Дасти)
A12: Этапы пути пользователя | B12: Вести реестр лошадей | C12: Учитывать размещение и перемещения | D12: Вносить записи о лошадях | E12: Получать справки | F12: Проверять пары | G12: Принимать заявки и вести очередь | H12: Следить за загрузкой и запасами
A13: Сделать обязательно (Must) | B13: OW-01 ИСР 3.1 Реестр лошадей трёх категорий | C13: OW-04 ИСР 3.2 Зафиксировать прибытие лошади | D13: OW-07 ИСР 3.3 Запись о готовности кобылы | E13: OW-10 ИСР 3.4 Справка «История жеребца» | F13: OW-13 ИСР 4.2 Проверить пару лошадей
B14: OW-02 ИСР 3.1 Карточка лошади с родословной | C14: OW-05 ИСР 3.2 Зафиксировать отъезд лошади | D14: OW-08 ИСР 3.3 Запись о травме или происшествии | E14: OW-11 ИСР 3.5 Справка «Перемещения и контакты» | F14: OW-14 ИСР 4.2 Причина запрета пары
B15: OW-03 ИСР 3.1 Добавить лошадь в реестр | C15: OW-06 ИСР 3.2 Где стоит лошадь и где была | D15: OW-09 ИСР 3.3 Запись о состоянии лошади | F15: OW-15 ИСР 4.1 Таблица правил совместимости
A16: Хорошо бы сделать (Should) | E16: OW-12 ИСР 6.1 Выгрузить справку файлом (заглушка) | G16: OW-16 ИСР 5.1 Входящие заявки клиентов
G17: OW-17 ИСР 5.1 Принять или отклонить заявку
G18: OW-18 ИСР 4.3 Очередь на каждого жеребца вариант Б: исключён
G19: OW-19 ИСР 4.3 Календарь занятости жеребцов вариант Б: исключён
A20: Можно будет сделать (Could) | H20: OW-20 ИСР 5.4 Отчёт о загрузке жеребцов вариант Б: исключён
H21: OW-21 ИСР 5.4 Напоминание «проверь запас» вариант Б: исключён
A23: Сотрудник ранчо, представление «Финансы» (Тэмми)
A24: Этапы пути пользователя | B24: Выставить счёт | C24: Контролировать оплату | D24: Анализировать финансы
A25: Хорошо бы сделать (Should) | B25: FN-01 ИСР 5.3 Счёт по факту случки вариант Б: исключён | C25: FN-03 ИСР 5.3 Статусы счетов вариант Б: исключён
B26: FN-02 ИСР 5.3 Счёт за период вариант Б: исключён | C26: FN-04 ИСР 5.3 Принять платёж (заглушка) вариант Б: исключён
B27: FN-05 ИСР 5.3 Случки без выставленного счёта вариант Б: исключён
A28: Можно будет сделать (Could) | D28: FN-06 ИСР 5.4 Финансовая сводка вариант Б: исключён
A30: Сквозные и обеспечивающие истории (для всех ролей)
A31: Этапы пути пользователя | B31: Доступ и роли | C31: Внешний вид и язык | D31: Данные для показа | E31: Внешние сервисы
A32: Сделать обязательно (Must) | B32: SH-01 ИСР 2.4 Вход и выбор роли | C32: SH-02 ИСР 2.3 Стиль «племенной книги» | D32: SH-04 ИСР 2.5 Демонстрационные данные | E32: SH-05 ИСР 6.1 Заглушки пяти внешних сервисов
A33: Хорошо бы сделать (Should) | C33: SH-03 ИСР 2.3 Английский язык и адаптивная раскладка

Sheet Истории
A1: Пользовательские истории Stud Book и их связь с пакетами ИСР
A2: Приоритет — MoSCoW по уставу и сводной таблице оценок. Столбцы I, M, N, O, P заполняются формулами по листу «Связь с ИСР». Вес истории в пакете пока равен 1/N (N — число историй с этим основным пакетом); после покера планирования заменить долей по story points.
A4: ID | B4: Роль | C4: Представление | D4: Этап пути (колонка карты) | E4: История | F4: Приоритет MoSCoW | G4: Основной пакет ИСР | H4: Дополнительные пакеты ИСР | I4: Название основного пакета | J4: Требование или допущение (устав) | K4: Стороны (реестр) | L4: Критерий приёмки (п. 2.4) | M4: Веха по уставу | N4: Веха по базовому плану | O4: Статус в базовом плане | P4: Вес в пакете | Q4: Примечание
A5: CL-01 | B5: Клиент | C5: — | D5: Подать заявку | E5: Как клиент, я хочу подать заявку на случку кобылы через систему, чтобы не звонить на ранчо. | F5: Should | G5: 5.1 | I5: =IFERROR(INDEX('Связь с ИСР'!$B$5:$B$29,MATCH($G5,'Связь с ИСР'!$A$5:$A$29,0)),"") -> Кабинет клиента и заявки | J5: Т-09 | K5: С-03, С-10 | L5: 8 | M5: =IFERROR(INDEX('Связь с ИСР'!$F$5:$F$29,MATCH($G5,'Связь с ИСР'!$A$5:$A$29,0)),"") -> В3 | N5: =IFERROR(INDEX('Связь с ИСР'!$G$5:$G$29,MATCH($G5,'Связь с ИСР'!$A$5:$A$29,0)),"") -> В4 | O5: =IF(N5="исключён","исключена из базового плана (вариант Б)","в плане") -> в плане | P5: =1/COUNTIF($G$5:$G$45,$G5) -> 0.16666667
A6: CL-02 | B6: Клиент | C6: — | D6: Подать заявку | E6: Как клиент, я хочу указать в заявке кобылу, жеребца и желаемый период, чтобы ранчо могло сразу проверить пару и назначить дату. | F6: Should | G6: 5.1 | H6: 3.1 | I6: =IFERROR(INDEX('Связь с ИСР'!$B$5:$B$29,MATCH($G6,'Связь с ИСР'!$A$5:$A$29,0)),"") -> Кабинет клиента и заявки | J6: Т-09 | K6: С-03, С-10 | L6: 8 | M6: =IFERROR(INDEX('Связь с ИСР'!$F$5:$F$29,MATCH($G6,'Связь с ИСР'!$A$5:$A$29,0)),"") -> В3 | N6: =IFERROR(INDEX('Связь с ИСР'!$G$5:$G$29,MATCH($G6,'Связь с ИСР'!$A$5:$A$29,0)),"") -> В4 | O6: =IF(N6="исключён","исключена из базового плана (вариант Б)","в плане") -> в плане | P6: =1/COUNTIF($G$5:$G$45,$G6) -> 0.16666667 | Q6: Вывод команды, подтвердить с заказчиком
A7: CL-03 | B7: Клиент | C7: — | D7: Заказать семя | E7: Как удалённый клиент, я хочу заказать семя жеребца с доставкой, чтобы не везти кобылу в Техас. | F7: Should | G7: 5.2 | H7: 4.3 | I7: =IFERROR(INDEX('Связь с ИСР'!$B$5:$B$29,MATCH($G7,'Связь с ИСР'!$A$5:$A$29,0)),"") -> Заказ семени с доставкой | J7: Т-09; А-13 | K7: С-03, С-10 | L7: 8 | M7: =IFERROR(INDEX('Связь с ИСР'!$F$5:$F$29,MATCH($G7,'Связь с ИСР'!$A$5:$A$29,0)),"") -> В3 | N7: =IFERROR(INDEX('Связь с ИСР'!$G$5:$G$29,MATCH($G7,'Связь с ИСР'!$A$5:$A$29,0)),"") -> исключён | O7: =IF(N7="исключён","исключена из базового плана (вариант Б)","в плане") -> исключена из базового плана (вариант Б) | P7: =1/COUNTIF($G$5:$G$45,$G7) -> 0.5
A8: CL-04 | B8: Клиент | C8: — | D8: Заказать семя | E8: Как удалённый клиент, я хочу указать адрес доставки и видеть её статус, чтобы знать, когда ждать семя. | F8: Should | G8: 5.2 | I8: =IFERROR(INDEX('Связь с ИСР'!$B$5:$B$29,MATCH($G8,'Связь с ИСР'!$A$5:$A$29,0)),"") -> Заказ семени с доставкой | J8: Т-09; А-4 | K8: С-03, С-10 | L8: 8 | M8: =IFERROR(INDEX('Связь с ИСР'!$F$5:$F$29,MATCH($G8,'Связь с ИСР'!$A$5:$A$29,0)),"") -> В3 | N8: =IFERROR(INDEX('Связь с ИСР'!$G$5:$G$29,MATCH($G8,'Связь с ИСР'!$A$5:$A$29,0)),"") -> исключён | O8: =IF(N8="исключён","исключена из базового плана (вариант Б)","в плане") -> исключена из базового плана (вариант Б) | P8: =1/COUNTIF($G$5:$G$45,$G8) -> 0.5
A9: CL-05 | B9: Клиент | C9: — | D9: Следить за заявкой | E9: Как клиент, я хочу видеть статус своей заявки, чтобы не уточнять его по телефону. | F9: Should | G9: 5.1 | I9: =IFERROR(INDEX('Связь с ИСР'!$B$5:$B$29,MATCH($G9,'Связь с ИСР'!$A$5:$A$29,0)),"") -> Кабинет клиента и заявки | J9: Т-09 | K9: С-03, С-10 | L9: 8 | M9: =IFERROR(INDEX('Связь с ИСР'!$F$5:$F$29,MATCH($G9,'Связь с ИСР'!$A$5:$A$29,0)),"") -> В3 | N9: =IFERROR(INDEX('Связь с ИСР'!$G$5:$G$29,MATCH($G9,'Связь с ИСР'!$A$5:$A$29,0)),"") -> В4 | O9: =IF(N9="исключён","исключена из базового плана (вариант Б)","в плане") -> в плане | P9: =1/COUNTIF($G$5:$G$45,$G9) -> 0.16666667
A10: CL-06 | B10: Клиент | C10: — | D10: Следить за заявкой | E10: Как клиент, я хочу видеть историю своих заявок, чтобы знать, что и когда я заказывал. | F10: Should | G10: 5.1 | I10: =IFERROR(INDEX('Связь с ИСР'!$B$5:$B$29,MATCH($G10,'Связь с ИСР'!$A$5:$A$29,0)),"") -> Кабинет клиента и заявки | J10: Т-09 | K10: С-03, С-10 | L10: 8 | M10: =IFERROR(INDEX('Связь с ИСР'!$F$5:$F$29,MATCH($G10,'Связь с ИСР'!$A$5:$A$29,0)),"") -> В3 | N10: =IFERROR(INDEX('Связь с ИСР'!$G$5:$G$29,MATCH($G10,'Связь с ИСР'!$A$5:$A$29,0)),"") -> В4 | O10: =IF(N10="исключён","исключена из базового плана (вариант Б)","в плане") -> в плане | P10: =1/COUNTIF($G$5:$G$45,$G10) -> 0.16666667
A11: CL-07 | B11: Клиент | C11: — | D11: Следить за заявкой | E11: Как клиент, я хочу получать уведомление об изменении статуса заявки, чтобы не заходить в систему без необходимости. | F11: Could | G11: 6.1 | H11: 5.1 | I11: =IFERROR(INDEX('Связь с ИСР'!$B$5:$B$29,MATCH($G11,'Связь с ИСР'!$A$5:$A$29,0)),"") -> Интеграция внешних сервисов (заглушки) | J11: А-2 | K11: С-03 | L11: 13 | M11: =IFERROR(INDEX('Связь с ИСР'!$F$5:$F$29,MATCH($G11,'Связь с ИСР'!$A$5:$A$29,0)),"") -> В2–В4 | N11: =IFERROR(INDEX('Связь с ИСР'!$G$5:$G$29,MATCH($G11,'Связь с ИСР'!$A$5:$A$29,0)),"") -> В2 | O11: =IF(N11="исключён","исключена из базового плана (вариант Б)","в плане") -> в плане | P11: =1/COUNTIF($G$5:$G$45,$G11) -> 0.33333333 | Q11: Срок следует за пакетом 5.1
A12: CL-08 | B12: Клиент | C12: — | D12: Получить и оплатить счёт | E12: Как клиент, я хочу видеть выставленные мне счета и статус оплаты, чтобы понимать, за что и сколько я должен. | F12: Should | G12: 5.3 | I12: =IFERROR(INDEX('Связь с ИСР'!$B$5:$B$29,MATCH($G12,'Связь с ИСР'!$A$5:$A$29,0)),"") -> Счета и платежи | J12: Т-10 | K12: С-02, С-03 | L12: 10 | M12: =IFERROR(INDEX('Связь с ИСР'!$F$5:$F$29,MATCH($G12,'Связь с ИСР'!$A$5:$A$29,0)),"") -> В4 | N12: =IFERROR(INDEX('Связь с ИСР'!$G$5:$G$29,MATCH($G12,'Связь с ИСР'!$A$5:$A$29,0)),"") -> исключён | O12: =IF(N12="исключён","исключена из базового плана (вариант Б)","в плане") -> исключена из базового плана (вариант Б) | P12: =1/COUNTIF($G$5:$G$45,$G12) -> 0.14285714
A13: CL-09 | B13: Клиент | C13: — | D13: Получить и оплатить счёт | E13: Как клиент, я хочу оплатить счёт в системе, чтобы не отправлять деньги отдельно. | F13: Should | G13: 5.3 | H13: 6.1 | I13: =IFERROR(INDEX('Связь с ИСР'!$B$5:$B$29,MATCH($G13,'Связь с ИСР'!$A$5:$A$29,0)),"") -> Счета и платежи | J13: Т-10; А-1 | K13: С-02, С-03 | L13: 10 | M13: =IFERROR(INDEX('Связь с ИСР'!$F$5:$F$29,MATCH($G13,'Связь с ИСР'!$A$5:$A$29,0)),"") -> В4 | N13: =IFERROR(INDEX('Связь с ИСР'!$G$5:$G$29,MATCH($G13,'Связь с ИСР'!$A$5:$A$29,0)),"") -> исключён | O13: =IF(N13="исключён","исключена из базового плана (вариант Б)","в плане") -> исключена из базового плана (вариант Б) | P13: =1/COUNTIF($G$5:$G$45,$G13) -> 0.14285714
A14: OW-01 | B14: Сотрудник ранчо | C14: Владелец (Дасти) | D14: Вести реестр лошадей | E14: Как сотрудник ранчо, я хочу видеть реестр лошадей трёх категорий (свои жеребцы, жеребцы на управлении, кобылы клиентов), чтобы знать, кто есть на ранчо. | F14: Must | G14: 3.1 | I14: =IFERROR(INDEX('Связь с ИСР'!$B$5:$B$29,MATCH($G14,'Связь с ИСР'!$A$5:$A$29,0)),"") -> Реестр лошадей и карточка лошади | J14: Т-01 | K14: С-06, С-12 | L14: 1 | M14: =IFERROR(INDEX('Связь с ИСР'!$F$5:$F$29,MATCH($G14,'Связь с ИСР'!$A$5:$A$29,0)),"") -> В1 | N14: =IFERROR(INDEX('Связь с ИСР'!$G$5:$G$29,MATCH($G14,'Связь с ИСР'!$A$5:$A$29,0)),"") -> В1 | O14: =IF(N14="исключён","исключена из базового плана (вариант Б)","в плане") -> в плане | P14: =1/COUNTIF($G$5:$G$45,$G14) -> 0.33333333
A15: OW-02 | B15: Сотрудник ранчо | C15: Владелец (Дасти) | D15: Вести реестр лошадей | E15: Как сотрудник ранчо, я хочу открыть карточку лошади с родословной минимум на два поколения, чтобы проверять происхождение без бумажного журнала. | F15: Must | G15: 3.1 | I15: =IFERROR(INDEX('Связь с ИСР'!$B$5:$B$29,MATCH($G15,'Связь с ИСР'!$A$5:$A$29,0)),"") -> Реестр лошадей и карточка лошади | J15: Т-01 | K15: С-06, С-12 | L15: 1 | M15: =IFERROR(INDEX('Связь с ИСР'!$F$5:$F$29,MATCH($G15,'Связь с ИСР'!$A$5:$A$29,0)),"") -> В1 | N15: =IFERROR(INDEX('Связь с ИСР'!$G$5:$G$29,MATCH($G15,'Связь с ИСР'!$A$5:$A$29,0)),"") -> В1 | O15: =IF(N15="исключён","исключена из базового плана (вариант Б)","в плане") -> в плане | P15: =1/COUNTIF($G$5:$G$45,$G15) -> 0.33333333
A16: OW-03 | B16: Сотрудник ранчо | C16: Владелец (Дасти) | D16: Вести реестр лошадей | E16: Как сотрудник ранчо, я хочу добавить лошадь в реестр и указать её происхождение, чтобы реестр оставался актуальным. | F16: Must | G16: 3.1 | I16: =IFERROR(INDEX('Связь с ИСР'!$B$5:$B$29,MATCH($G16,'Связь с ИСР'!$A$5:$A$29,0)),"") -> Реестр лошадей и карточка лошади | J16: Т-01 | K16: С-06, С-12 | L16: 1 | M16: =IFERROR(INDEX('Связь с ИСР'!$F$5:$F$29,MATCH($G16,'Связь с ИСР'!$A$5:$A$29,0)),"") -> В1 | N16: =IFERROR(INDEX('Связь с ИСР'!$G$5:$G$29,MATCH($G16,'Связь с ИСР'!$A$5:$A$29,0)),"") -> В1 | O16: =IF(N16="исключён","исключена из базового плана (вариант Б)","в плане") -> в плане | P16: =1/COUNTIF($G$5:$G$45,$G16) -> 0.33333333 | Q16: Вывод команды, подтвердить с заказчиком
A17: OW-04 | B17: Сотрудник ранчо | C17: Владелец (Дасти) | D17: Учитывать размещение и перемещения | E17: Как сотрудник ранчо, я хочу зафиксировать прибытие лошади (дата, место, откуда прибыла), чтобы всегда знать, откуда она появилась. | F17: Must | G17: 3.2 | I17: =IFERROR(INDEX('Связь с ИСР'!$B$5:$B$29,MATCH($G17,'Связь с ИСР'!$A$5:$A$29,0)),"") -> Размещение и перемещения | J17: Т-02; А-8 | K17: С-08 | L17: 2 | M17: =IFERROR(INDEX('Связь с ИСР'!$F$5:$F$29,MATCH($G17,'Связь с ИСР'!$A$5:$A$29,0)),"") -> В1 | N17: =IFERROR(INDEX('Связь с ИСР'!$G$5:$G$29,MATCH($G17,'Связь с ИСР'!$A$5:$A$29,0)),"") -> В2 | O17: =IF(N17="исключён","исключена из базового плана (вариант Б)","в плане") -> в плане | P17: =1/COUNTIF($G$5:$G$45,$G17) -> 0.33333333
A18: OW-05 | B18: Сотрудник ранчо | C18: Владелец (Дасти) | D18: Учитывать размещение и перемещения | E18: Как сотрудник ранчо, я хочу зафиксировать отъезд лошади, чтобы реестр показывал только тех, кто сейчас на ранчо. | F18: Must | G18: 3.2 | I18: =IFERROR(INDEX('Связь с ИСР'!$B$5:$B$29,MATCH($G18,'Связь с ИСР'!$A$5:$A$29,0)),"") -> Размещение и перемещения | J18: Т-02; А-8 | K18: С-08 | L18: 2 | M18: =IFERROR(INDEX('Связь с ИСР'!$F$5:$F$29,MATCH($G18,'Связь с ИСР'!$A$5:$A$29,0)),"") -> В1 | N18: =IFERROR(INDEX('Связь с ИСР'!$G$5:$G$29,MATCH($G18,'Связь с ИСР'!$A$5:$A$29,0)),"") -> В2 | O18: =IF(N18="исключён","исключена из базового плана (вариант Б)","в плане") -> в плане | P18: =1/COUNTIF($G$5:$G$45,$G18) -> 0.33333333
A19: OW-06 | B19: Сотрудник ранчо | C19: Владелец (Дасти) | D19: Учитывать размещение и перемещения | E19: Как сотрудник ранчо, я хочу видеть, где сейчас стоит лошадь и где она была раньше, чтобы быстро отвечать на вопросы клиентов и регуляторов. | F19: Must | G19: 3.2 | H19: 3.1 | I19: =IFERROR(INDEX('Связь с ИСР'!$B$5:$B$29,MATCH($G19,'Связь с ИСР'!$A$5:$A$29,0)),"") -> Размещение и перемещения | J19: Т-02; А-8 | K19: С-08 | L19: 2 | M19: =IFERROR(INDEX('Связь с ИСР'!$F$5:$F$29,MATCH($G19,'Связь с ИСР'!$A$5:$A$29,0)),"") -> В1 | N19: =IFERROR(INDEX('Связь с ИСР'!$G$5:$G$29,MATCH($G19,'Связь с ИСР'!$A$5:$A$29,0)),"") -> В2 | O19: =IF(N19="исключён","исключена из базового плана (вариант Б)","в плане") -> в плане | P19: =1/COUNTIF($G$5:$G$45,$G19) -> 0.33333333
A20: OW-07 | B20: Сотрудник ранчо | C20: Владелец (Дасти) | D20: Вносить записи о лошадях | E20: Как сотрудник ранчо, я хочу внести запись о готовности кобылы простой формой (не более семи полей и трёх шагов), чтобы сведения ветеринара не терялись. | F20: Must | G20: 3.3 | I20: =IFERROR(INDEX('Связь с ИСР'!$B$5:$B$29,MATCH($G20,'Связь с ИСР'!$A$5:$A$29,0)),"") -> Ввод записей о состоянии и происшествиях | J20: Т-06; Т-15; А-10 | K20: С-01, С-04, С-07 | L20: 6 | M20: =IFERROR(INDEX('Связь с ИСР'!$F$5:$F$29,MATCH($G20,'Связь с ИСР'!$A$5:$A$29,0)),"") -> В2 | N20: =IFERROR(INDEX('Связь с ИСР'!$G$5:$G$29,MATCH($G20,'Связь с ИСР'!$A$5:$A$29,0)),"") -> В2 | O20: =IF(N20="исключён","исключена из базового плана (вариант Б)","в плане") -> в плане | P20: =1/COUNTIF($G$5:$G$45,$G20) -> 0.33333333
A21: OW-08 | B21: Сотрудник ранчо | C21: Владелец (Дасти) | D21: Вносить записи о лошадях | E21: Как сотрудник ранчо, я хочу внести запись о травме или происшествии, чтобы она попадала в историю лошади. | F21: Must | G21: 3.3 | I21: =IFERROR(INDEX('Связь с ИСР'!$B$5:$B$29,MATCH($G21,'Связь с ИСР'!$A$5:$A$29,0)),"") -> Ввод записей о состоянии и происшествиях | J21: Т-06; А-10 | K21: С-01, С-04, С-07 | L21: 6 | M21: =IFERROR(INDEX('Связь с ИСР'!$F$5:$F$29,MATCH($G21,'Связь с ИСР'!$A$5:$A$29,0)),"") -> В2 | N21: =IFERROR(INDEX('Связь с ИСР'!$G$5:$G$29,MATCH($G21,'Связь с ИСР'!$A$5:$A$29,0)),"") -> В2 | O21: =IF(N21="исключён","исключена из базового плана (вариант Б)","в плане") -> в плане | P21: =1/COUNTIF($G$5:$G$45,$G21) -> 0.33333333
A22: OW-09 | B22: Сотрудник ранчо | C22: Владелец (Дасти) | D22: Вносить записи о лошадях | E22: Как сотрудник ранчо, я хочу внести запись о состоянии лошади, чтобы история была полной. | F22: Must | G22: 3.3 | I22: =IFERROR(INDEX('Связь с ИСР'!$B$5:$B$29,MATCH($G22,'Связь с ИСР'!$A$5:$A$29,0)),"") -> Ввод записей о состоянии и происшествиях | J22: Т-06; Т-15 | K22: С-01, С-04, С-07 | L22: 6 | M22: =IFERROR(INDEX('Связь с ИСР'!$F$5:$F$29,MATCH($G22,'Связь с ИСР'!$A$5:$A$29,0)),"") -> В2 | N22: =IFERROR(INDEX('Связь с ИСР'!$G$5:$G$29,MATCH($G22,'Связь с ИСР'!$A$5:$A$29,0)),"") -> В2 | O22: =IF(N22="исключён","исключена из базового плана (вариант Б)","в плане") -> в плане | P22: =1/COUNTIF($G$5:$G$45,$G22) -> 0.33333333
A23: OW-10 | B23: Сотрудник ранчо | C23: Владелец (Дасти) | D23: Получать справки | E23: Как сотрудник ранчо, я хочу собрать историю жеребца (число случек за сезон, происшествия, записи о состоянии) не более чем за три перехода, чтобы показать её страховщику. | F23: Must | G23: 3.4 | H23: 3.3 | I23: =IFERROR(INDEX('Связь с ИСР'!$B$5:$B$29,MATCH($G23,'Связь с ИСР'!$A$5:$A$29,0)),"") -> Справка «История жеребца» | J23: Т-03 | K23: С-09 | L23: 3 | M23: =IFERROR(INDEX('Связь с ИСР'!$F$5:$F$29,MATCH($G23,'Связь с ИСР'!$A$5:$A$29,0)),"") -> В2 | N23: =IFERROR(INDEX('Связь с ИСР'!$G$5:$G$29,MATCH($G23,'Связь с ИСР'!$A$5:$A$29,0)),"") -> В3 | O23: =IF(N23="исключён","исключена из базового плана (вариант Б)","в плане") -> в плане | P23: =1/COUNTIF($G$5:$G$45,$G23) -> 1
A24: OW-11 | B24: Сотрудник ранчо | C24: Владелец (Дасти) | D24: Получать справки | E24: Как сотрудник ранчо, я хочу получить справку о перемещениях и контактах лошадей за период, чтобы при вспышке болезни за пять минут показать, какие лошади были на ранчо, откуда прибыли и с кем контактировали. | F24: Must | G24: 3.5 | H24: 3.2; 3.3 | I24: =IFERROR(INDEX('Связь с ИСР'!$B$5:$B$29,MATCH($G24,'Связь с ИСР'!$A$5:$A$29,0)),"") -> Справка «Перемещения и контакты» | J24: Т-04; А-7 | K24: С-08 | L24: 4 | M24: =IFERROR(INDEX('Связь с ИСР'!$F$5:$F$29,MATCH($G24,'Связь с ИСР'!$A$5:$A$29,0)),"") -> В2 | N24: =IFERROR(INDEX('Связь с ИСР'!$G$5:$G$29,MATCH($G24,'Связь с ИСР'!$A$5:$A$29,0)),"") -> В3 | O24: =IF(N24="исключён","исключена из базового плана (вариант Б)","в плане") -> в плане | P24: =1/COUNTIF($G$5:$G$45,$G24) -> 1
A25: OW-12 | B25: Сотрудник ранчо | C25: Владелец (Дасти) | D25: Получать справки | E25: Как сотрудник ранчо, я хочу выгрузить справку в файл, чтобы передать её страховщику или регулятору. | F25: Should | G25: 6.1 | H25: 3.4; 3.5 | I25: =IFERROR(INDEX('Связь с ИСР'!$B$5:$B$29,MATCH($G25,'Связь с ИСР'!$A$5:$A$29,0)),"") -> Интеграция внешних сервисов (заглушки) | J25: Т-05; А-5 | K25: С-08, С-09 | L25: 5 | M25: =IFERROR(INDEX('Связь с ИСР'!$F$5:$F$29,MATCH($G25,'Связь с ИСР'!$A$5:$A$29,0)),"") -> В2–В4 | N25: =IFERROR(INDEX('Связь с ИСР'!$G$5:$G$29,MATCH($G25,'Связь с ИСР'!$A$5:$A$29,0)),"") -> В2 | O25: =IF(N25="исключён","исключена из базового плана (вариант Б)","в плане") -> в плане | P25: =1/COUNTIF($G$5:$G$45,$G25) -> 0.33333333 | Q25: Срок следует за пакетами 3.4 и 3.5
A26: OW-13 | B26: Сотрудник ранчо | C26: Владелец (Дасти) | D26: Проверять пары | E26: Как сотрудник ранчо, я хочу проверить пару лошадей на допустимость, чтобы не случить тех, кого нельзя. | F26: Must | G26: 4.2 | H26: 3.1; 4.1 | I26: =IFERROR(INDEX('Связь с ИСР'!$B$5:$B$29,MATCH($G26,'Связь с ИСР'!$A$5:$A$29,0)),"") -> Проверка совместимости пар | J26: Т-07 | K26: С-01, С-07 | L26: 7 | M26: =IFERROR(INDEX('Связь с ИСР'!$F$5:$F$29,MATCH($G26,'Связь с ИСР'!$A$5:$A$29,0)),"") -> В3 | N26: =IFERROR(INDEX('Связь с ИСР'!$G$5:$G$29,MATCH($G26,'Связь с ИСР'!$A$5:$A$29,0)),"") -> В4 | O26: =IF(N26="исключён","исключена из базового плана (вариант Б)","в плане") -> в плане | P26: =1/COUNTIF($G$5:$G$45,$G26) -> 0.5
A27: OW-14 | B27: Сотрудник ранчо | C27: Владелец (Дасти) | D27: Проверять пары | E27: Как сотрудник ранчо, я хочу видеть причину запрета (родство, занятость жеребца, неготовность кобылы), чтобы понимать, почему пара недопустима. | F27: Must | G27: 4.2 | H27: 4.1 | I27: =IFERROR(INDEX('Связь с ИСР'!$B$5:$B$29,MATCH($G27,'Связь с ИСР'!$A$5:$A$29,0)),"") -> Проверка совместимости пар | J27: Т-07 | K27: С-01, С-07 | L27: 7 | M27: =IFERROR(INDEX('Связь с ИСР'!$F$5:$F$29,MATCH($G27,'Связь с ИСР'!$A$5:$A$29,0)),"") -> В3 | N27: =IFERROR(INDEX('Связь с ИСР'!$G$5:$G$29,MATCH($G27,'Связь с ИСР'!$A$5:$A$29,0)),"") -> В4 | O27: =IF(N27="исключён","исключена из базового плана (вариант Б)","в плане") -> в плане | P27: =1/COUNTIF($G$5:$G$45,$G27) -> 0.5
A28: OW-15 | B28: Сотрудник ранчо | C28: Владелец (Дасти) | D28: Проверять пары | E28: Как сотрудник ранчо, я хочу, чтобы правила допустимости пар хранились единой таблицей, согласованной с ветеринаром, чтобы все проверки шли по одним правилам. | F28: Must | G28: 4.1 | I28: =IFERROR(INDEX('Связь с ИСР'!$B$5:$B$29,MATCH($G28,'Связь с ИСР'!$A$5:$A$29,0)),"") -> Формализация правил совместимости | J28: Т-07; А-9 | K28: С-01, С-07 | L28: 7 | M28: =IFERROR(INDEX('Связь с ИСР'!$F$5:$F$29,MATCH($G28,'Связь с ИСР'!$A$5:$A$29,0)),"") -> В1 | N28: =IFERROR(INDEX('Связь с ИСР'!$G$5:$G$29,MATCH($G28,'Связь с ИСР'!$A$5:$A$29,0)),"") -> В1 | O28: =IF(N28="исключён","исключена из базового плана (вариант Б)","в плане") -> в плане | P28: =1/COUNTIF($G$5:$G$45,$G28) -> 1 | Q28: Условие для 4.2; таблицу даёт заказчик (А-9)
A29: OW-16 | B29: Сотрудник ранчо | C29: Владелец (Дасти) | D29: Принимать заявки и вести очередь | E29: Как сотрудник ранчо, я хочу видеть входящие заявки клиентов и их статусы, чтобы ни одна заявка не потерялась. | F29: Should | G29: 5.1 | I29: =IFERROR(INDEX('Связь с ИСР'!$B$5:$B$29,MATCH($G29,'Связь с ИСР'!$A$5:$A$29,0)),"") -> Кабинет клиента и заявки | J29: Т-09 | K29: С-03, С-10 | L29: 8 | M29: =IFERROR(INDEX('Связь с ИСР'!$F$5:$F$29,MATCH($G29,'Связь с ИСР'!$A$5:$A$29,0)),"") -> В3 | N29: =IFERROR(INDEX('Связь с ИСР'!$G$5:$G$29,MATCH($G29,'Связь с ИСР'!$A$5:$A$29,0)),"") -> В4 | O29: =IF(N29="исключён","исключена из базового плана (вариант Б)","в плане") -> в плане | P29: =1/COUNTIF($G$5:$G$45,$G29) -> 0.16666667 | Q29: Вывод команды, подтвердить с заказчиком
A30: OW-17 | B30: Сотрудник ранчо | C30: Владелец (Дасти) | D30: Принимать заявки и вести очередь | E30: Как сотрудник ранчо, я хочу принять или отклонить заявку после проверки пары, чтобы клиент получил ответ с причиной. | F30: Should | G30: 5.1 | H30: 4.2 | I30: =IFERROR(INDEX('Связь с ИСР'!$B$5:$B$29,MATCH($G30,'Связь с ИСР'!$A$5:$A$29,0)),"") -> Кабинет клиента и заявки | J30: Т-09; Т-07 | K30: С-01, С-03, С-07, С-10 | L30: 11 | M30: =IFERROR(INDEX('Связь с ИСР'!$F$5:$F$29,MATCH($G30,'Связь с ИСР'!$A$5:$A$29,0)),"") -> В3 | N30: =IFERROR(INDEX('Связь с ИСР'!$G$5:$G$29,MATCH($G30,'Связь с ИСР'!$A$5:$A$29,0)),"") -> В4 | O30: =IF(N30="исключён","исключена из базового плана (вариант Б)","в плане") -> в плане | P30: =1/COUNTIF($G$5:$G$45,$G30) -> 0.16666667 | Q30: Вывод команды, подтвердить с заказчиком
A31: OW-18 | B31: Сотрудник ранчо | C31: Владелец (Дасти) | D31: Принимать заявки и вести очередь | E31: Как сотрудник ранчо, я хочу видеть очередь на каждого жеребца (случка и заказ семени), чтобы знать, кто следующий. | F31: Should | G31: 4.3 | H31: 5.1 | I31: =IFERROR(INDEX('Связь с ИСР'!$B$5:$B$29,MATCH($G31,'Связь с ИСР'!$A$5:$A$29,0)),"") -> Очередь и календарь жеребцов | J31: Т-08; А-13 | K31: С-01 | L31: 9 | M31: =IFERROR(INDEX('Связь с ИСР'!$F$5:$F$29,MATCH($G31,'Связь с ИСР'!$A$5:$A$29,0)),"") -> В3 | N31: =IFERROR(INDEX('Связь с ИСР'!$G$5:$G$29,MATCH($G31,'Связь с ИСР'!$A$5:$A$29,0)),"") -> исключён | O31: =IF(N31="исключён","исключена из базового плана (вариант Б)","в плане") -> исключена из базового плана (вариант Б) | P31: =1/COUNTIF($G$5:$G$45,$G31) -> 0.5
A32: OW-19 | B32: Сотрудник ранчо | C32: Владелец (Дасти) | D32: Принимать заявки и вести очередь | E32: Как сотрудник ранчо, я хочу видеть календарь занятости жеребцов, чтобы не назначать двух кобыл на одно время. | F32: Should | G32: 4.3 | I32: =IFERROR(INDEX('Связь с ИСР'!$B$5:$B$29,MATCH($G32,'Связь с ИСР'!$A$5:$A$29,0)),"") -> Очередь и календарь жеребцов | J32: Т-08 | K32: С-01 | L32: 9 | M32: =IFERROR(INDEX('Связь с ИСР'!$F$5:$F$29,MATCH($G32,'Связь с ИСР'!$A$5:$A$29,0)),"") -> В3 | N32: =IFERROR(INDEX('Связь с ИСР'!$G$5:$G$29,MATCH($G32,'Связь с ИСР'!$A$5:$A$29,0)),"") -> исключён | O32: =IF(N32="исключён","исключена из базового плана (вариант Б)","в плане") -> исключена из базового плана (вариант Б) | P32: =1/COUNTIF($G$5:$G$45,$G32) -> 0.5
A33: OW-20 | B33: Сотрудник ранчо | C33: Владелец (Дасти) | D33: Следить за загрузкой и запасами | E33: Как сотрудник ранчо, я хочу видеть отчёт о загрузке жеребцов, чтобы решать, сколько кобыл принимать. | F33: Could | G33: 5.4 | H33: 4.3 | I33: =IFERROR(INDEX('Связь с ИСР'!$B$5:$B$29,MATCH($G33,'Связь с ИСР'!$A$5:$A$29,0)),"") -> Отчёты и напоминания (Could) | J33: Т-11 | K33: С-01, С-02 | L33: 16 | M33: =IFERROR(INDEX('Связь с ИСР'!$F$5:$F$29,MATCH($G33,'Связь с ИСР'!$A$5:$A$29,0)),"") -> В4 | N33: =IFERROR(INDEX('Связь с ИСР'!$G$5:$G$29,MATCH($G33,'Связь с ИСР'!$A$5:$A$29,0)),"") -> исключён | O33: =IF(N33="исключён","исключена из базового плана (вариант Б)","в плане") -> исключена из базового плана (вариант Б) | P33: =1/COUNTIF($G$5:$G$45,$G33) -> 0.33333333
A34: OW-21 | B34: Сотрудник ранчо | C34: Владелец (Дасти) | D34: Следить за загрузкой и запасами | E34: Как сотрудник ранчо, я хочу получать напоминание «проверь запас» (азот, ёмкости, корм, подстилка), чтобы доставка семени не останавливалась из-за перебоев. | F34: Could | G34: 5.4 | I34: =IFERROR(INDEX('Связь с ИСР'!$B$5:$B$29,MATCH($G34,'Связь с ИСР'!$A$5:$A$29,0)),"") -> Отчёты и напоминания (Could) | J34: Т-12 | K34: С-11 | M34: =IFERROR(INDEX('Связь с ИСР'!$F$5:$F$29,MATCH($G34,'Связь с ИСР'!$A$5:$A$29,0)),"") -> В4 | N34: =IFERROR(INDEX('Связь с ИСР'!$G$5:$G$29,MATCH($G34,'Связь с ИСР'!$A$5:$A$29,0)),"") -> исключён | O34: =IF(N34="исключён","исключена из базового плана (вариант Б)","в плане") -> исключена из базового плана (вариант Б) | P34: =1/COUNTIF($G$5:$G$45,$G34) -> 0.33333333
A35: FN-01 | B35: Сотрудник ранчо | C35: Финансы (Тэмми) | D35: Выставить счёт | E35: Как сотрудник ранчо (финансы), я хочу выставить клиенту счёт по факту случки одним действием, чтобы ни одна случка не осталась без счёта. | F35: Should | G35: 5.3 | I35: =IFERROR(INDEX('Связь с ИСР'!$B$5:$B$29,MATCH($G35,'Связь с ИСР'!$A$5:$A$29,0)),"") -> Счета и платежи | J35: Т-10 | K35: С-02 | L35: 10 | M35: =IFERROR(INDEX('Связь с ИСР'!$F$5:$F$29,MATCH($G35,'Связь с ИСР'!$A$5:$A$29,0)),"") -> В4 | N35: =IFERROR(INDEX('Связь с ИСР'!$G$5:$G$29,MATCH($G35,'Связь с ИСР'!$A$5:$A$29,0)),"") -> исключён | O35: =IF(N35="исключён","исключена из базового плана (вариант Б)","в плане") -> исключена из базового плана (вариант Б) | P35: =1/COUNTIF($G$5:$G$45,$G35) -> 0.14285714
A36: FN-02 | B36: Сотрудник ранчо | C36: Финансы (Тэмми) | D36: Выставить счёт | E36: Как сотрудник ранчо (финансы), я хочу выставить клиенту счёт за период одним действием, чтобы выставлять конюшням общий счёт. | F36: Should | G36: 5.3 | I36: =IFERROR(INDEX('Связь с ИСР'!$B$5:$B$29,MATCH($G36,'Связь с ИСР'!$A$5:$A$29,0)),"") -> Счета и платежи | J36: Т-10 | K36: С-02 | L36: 10 | M36: =IFERROR(INDEX('Связь с ИСР'!$F$5:$F$29,MATCH($G36,'Связь с ИСР'!$A$5:$A$29,0)),"") -> В4 | N36: =IFERROR(INDEX('Связь с ИСР'!$G$5:$G$29,MATCH($G36,'Связь с ИСР'!$A$5:$A$29,0)),"") -> исключён | O36: =IF(N36="исключён","исключена из базового плана (вариант Б)","в плане") -> исключена из базового плана (вариант Б) | P36: =1/COUNTIF($G$5:$G$45,$G36) -> 0.14285714
A37: FN-03 | B37: Сотрудник ранчо | C37: Финансы (Тэмми) | D37: Контролировать оплату | E37: Как сотрудник ранчо (финансы), я хочу видеть статусы счетов, чтобы понимать, кто ещё не заплатил. | F37: Should | G37: 5.3 | I37: =IFERROR(INDEX('Связь с ИСР'!$B$5:$B$29,MATCH($G37,'Связь с ИСР'!$A$5:$A$29,0)),"") -> Счета и платежи | J37: Т-10 | K37: С-02 | L37: 10 | M37: =IFERROR(INDEX('Связь с ИСР'!$F$5:$F$29,MATCH($G37,'Связь с ИСР'!$A$5:$A$29,0)),"") -> В4 | N37: =IFERROR(INDEX('Связь с ИСР'!$G$5:$G$29,MATCH($G37,'Связь с ИСР'!$A$5:$A$29,0)),"") -> исключён | O37: =IF(N37="исключён","исключена из базового плана (вариант Б)","в плане") -> исключена из базового плана (вариант Б) | P37: =1/COUNTIF($G$5:$G$45,$G37) -> 0.14285714
A38: FN-04 | B38: Сотрудник ранчо | C38: Финансы (Тэмми) | D38: Контролировать оплату | E38: Как сотрудник ранчо (финансы), я хочу отметить поступление платежа по счёту, чтобы статус счёта был актуальным. | F38: Should | G38: 5.3 | H38: 6.1 | I38: =IFERROR(INDEX('Связь с ИСР'!$B$5:$B$29,MATCH($G38,'Связь с ИСР'!$A$5:$A$29,0)),"") -> Счета и платежи | J38: Т-10; А-1 | K38: С-02 | L38: 10 | M38: =IFERROR(INDEX('Связь с ИСР'!$F$5:$F$29,MATCH($G38,'Связь с ИСР'!$A$5:$A$29,0)),"") -> В4 | N38: =IFERROR(INDEX('Связь с ИСР'!$G$5:$G$29,MATCH($G38,'Связь с ИСР'!$A$5:$A$29,0)),"") -> исключён | O38: =IF(N38="исключён","исключена из базового плана (вариант Б)","в плане") -> исключена из базового плана (вариант Б) | P38: =1/COUNTIF($G$5:$G$45,$G38) -> 0.14285714
A39: FN-05 | B39: Сотрудник ранчо | C39: Финансы (Тэмми) | D39: Выставить счёт | E39: Как сотрудник ранчо (финансы), я хочу видеть случки и заказы семени, по которым счёт ещё не выставлен, чтобы не терять деньги. | F39: Should | G39: 5.3 | I39: =IFERROR(INDEX('Связь с ИСР'!$B$5:$B$29,MATCH($G39,'Связь с ИСР'!$A$5:$A$29,0)),"") -> Счета и платежи | J39: Т-10 | K39: С-02 | L39: 10 | M39: =IFERROR(INDEX('Связь с ИСР'!$F$5:$F$29,MATCH($G39,'Связь с ИСР'!$A$5:$A$29,0)),"") -> В4 | N39: =IFERROR(INDEX('Связь с ИСР'!$G$5:$G$29,MATCH($G39,'Связь с ИСР'!$A$5:$A$29,0)),"") -> исключён | O39: =IF(N39="исключён","исключена из базового плана (вариант Б)","в плане") -> исключена из базового плана (вариант Б) | P39: =1/COUNTIF($G$5:$G$45,$G39) -> 0.14285714 | Q39: Вывод команды, подтвердить с заказчиком
A40: FN-06 | B40: Сотрудник ранчо | C40: Финансы (Тэмми) | D40: Анализировать финансы | E40: Как сотрудник ранчо (финансы), я хочу видеть финансовую сводку, чтобы понимать общую картину по выручке и долгам. | F40: Could | G40: 5.4 | H40: 5.3 | I40: =IFERROR(INDEX('Связь с ИСР'!$B$5:$B$29,MATCH($G40,'Связь с ИСР'!$A$5:$A$29,0)),"") -> Отчёты и напоминания (Could) | J40: Т-11 | K40: С-01, С-02 | L40: 16 | M40: =IFERROR(INDEX('Связь с ИСР'!$F$5:$F$29,MATCH($G40,'Связь с ИСР'!$A$5:$A$29,0)),"") -> В4 | N40: =IFERROR(INDEX('Связь с ИСР'!$G$5:$G$29,MATCH($G40,'Связь с ИСР'!$A$5:$A$29,0)),"") -> исключён | O40: =IF(N40="исключён","исключена из базового плана (вариант Б)","в плане") -> исключена из базового плана (вариант Б) | P40: =1/COUNTIF($G$5:$G$45,$G40) -> 0.33333333
A41: SH-01 | B41: Все роли | C41: — | D41: Доступ и роли | E41: Как пользователь системы, я хочу войти и выбрать роль (клиент или сотрудник ранчо), чтобы видеть только нужные мне экраны. | F41: Must | G41: 2.4 | H41: 2.2 | I41: =IFERROR(INDEX('Связь с ИСР'!$B$5:$B$29,MATCH($G41,'Связь с ИСР'!$A$5:$A$29,0)),"") -> Подготовка среды и инструментов | J41: А-11 | L41: 11 | M41: =IFERROR(INDEX('Связь с ИСР'!$F$5:$F$29,MATCH($G41,'Связь с ИСР'!$A$5:$A$29,0)),"") -> Фаза 4 | N41: =IFERROR(INDEX('Связь с ИСР'!$G$5:$G$29,MATCH($G41,'Связь с ИСР'!$A$5:$A$29,0)),"") -> Фаза 4 | O41: =IF(N41="исключён","исключена из базового плана (вариант Б)","в плане") -> в плане | P41: =1/COUNTIF($G$5:$G$45,$G41) -> 1 | Q41: Отдельного пакета ИСР для входа нет: отнесён к 2.4 и 2.2
...

Sheet Связь с ИСР
A1: Покрытие пакетов ИСР пользовательскими историями
A2: Пакеты, названия, приоритеты и ожидаемая трудоёмкость E взяты из сводной таблицы оценок (E = (O + 4M + P) / 6), вехи — из устава (п. 3.1) и расписания v1.0. Столбцы H, I, J, K считаются формулами по листу «Истории».
A4: № | B4: Пакет работ | C4: Тип | D4: Приоритет | E4: E ожидаемая, ч | F4: Веха по уставу | G4: Веха по базовому плану | H4: Историй (основной пакет) | I4: Историй (дополнительно) | J4: Сумма весов историй | K4: Как пакет попадает в бэклог
A5: 1.1 | B5: Инициация проекта | C5: непродуктовый | D5: Must | E5: 18.67 | F5: Фаза 2 | G5: Фаза 2 | H5: =COUNTIF(Истории!$G$5:$G$45,A5) -> 0 | I5: =COUNTIF(Истории!$H$5:$H$45,"*"&A5&"*") -> 0 | J5: =SUMIF(Истории!$G$5:$G$45,A5,Истории!$P$5:$P$45) -> 0 | K5: =IF(C5="непродуктовый","задачи бэклога, историй нет",IF(H5>0,"истории с основным пакетом","НЕТ ИСТОРИЙ")) -> задачи бэклога, историй нет
A6: 1.2 | B6: Планирование проекта | C6: непродуктовый | D6: Must | E6: 32.67 | F6: Фазы 3–4 | G6: Фаза 4 | H6: =COUNTIF(Истории!$G$5:$G$45,A6) -> 0 | I6: =COUNTIF(Истории!$H$5:$H$45,"*"&A6&"*") -> 0 | J6: =SUMIF(Истории!$G$5:$G$45,A6,Истории!$P$5:$P$45) -> 0 | K6: =IF(C6="непродуктовый","задачи бэклога, историй нет",IF(H6>0,"истории с основным пакетом","НЕТ ИСТОРИЙ")) -> задачи бэклога, историй нет
A7: 1.3 | B7: Мониторинг и контроль | C7: непродуктовый | D7: Must | E7: 61.67 | F7: весь проект | G7: весь проект | H7: =COUNTIF(Истории!$G$5:$G$45,A7) -> 0 | I7: =COUNTIF(Истории!$H$5:$H$45,"*"&A7&"*") -> 0 | J7: =SUMIF(Истории!$G$5:$G$45,A7,Истории!$P$5:$P$45) -> 0 | K7: =IF(C7="непродуктовый","задачи бэклога, историй нет",IF(H7>0,"истории с основным пакетом","НЕТ ИСТОРИЙ")) -> задачи бэклога, историй нет
A8: 1.4 | B8: Закрытие проекта | C8: непродуктовый | D8: Must | E8: 12.67 | F8: 26–31.12 | G8: после В4 | H8: =COUNTIF(Истории!$G$5:$G$45,A8) -> 0 | I8: =COUNTIF(Истории!$H$5:$H$45,"*"&A8&"*") -> 0 | J8: =SUMIF(Истории!$G$5:$G$45,A8,Истории!$P$5:$P$45) -> 0 | K8: =IF(C8="непродуктовый","задачи бэклога, историй нет",IF(H8>0,"истории с основным пакетом","НЕТ ИСТОРИЙ")) -> задачи бэклога, историй нет
A9: 2.1 | B9: Сбор и анализ требований | C9: непродуктовый | D9: Must | E9: 28.83 | F9: Фазы 2–4, далее по итерациям | G9: по итерациям | H9: =COUNTIF(Истории!$G$5:$G$45,A9) -> 0 | I9: =COUNTIF(Истории!$H$5:$H$45,"*"&A9&"*") -> 0 | J9: =SUMIF(Истории!$G$5:$G$45,A9,Истории!$P$5:$P$45) -> 0 | K9: =IF(C9="непродуктовый","задачи бэклога, историй нет",IF(H9>0,"истории с основным пакетом","НЕТ ИСТОРИЙ")) -> задачи бэклога, историй нет
A10: 2.2 | B10: Проектирование архитектуры и базы данных | C10: непродуктовый | D10: Must | E10: 31 | F10: Фаза 4 | G10: Фаза 4 | H10: =COUNTIF(Истории!$G$5:$G$45,A10) -> 0 | I10: =COUNTIF(Истории!$H$5:$H$45,"*"&A10&"*") -> 2 | J10: =SUMIF(Истории!$G$5:$G$45,A10,Истории!$P$5:$P$45) -> 0 | K10: =IF(C10="непродуктовый","задачи бэклога, историй нет",IF(H10>0,"истории с основным пакетом","НЕТ ИСТОРИЙ")) -> задачи бэклога, историй нет
A11: 2.3 | B11: Проектирование пользовательского интерфейса | C11: продуктовый | D11: Must | E11: 35.83 | F11: В1 | G11: Фаза 4 | H11: =COUNTIF(Истории!$G$5:$G$45,A11) -> 2 | I11: =COUNTIF(Истории!$H$5:$H$45,"*"&A11&"*") -> 0 | J11: =SUMIF(Истории!$G$5:$G$45,A11,Истории!$P$5:$P$45) -> 1 | K11: =IF(C11="непродуктовый","задачи бэклога, историй нет",IF(H11>0,"истории с основным пакетом","НЕТ ИСТОРИЙ")) -> истории с основным пакетом
A12: 2.4 | B12: Подготовка среды и инструментов | C12: продуктовый | D12: Must | E12: 16.67 | F12: Фаза 4 | G12: Фаза 4 | H12: =COUNTIF(Истории!$G$5:$G$45,A12) -> 1 | I12: =COUNTIF(Истории!$H$5:$H$45,"*"&A12&"*") -> 0 | J12: =SUMIF(Истории!$G$5:$G$45,A12,Истории!$P$5:$P$45) -> 1 | K12: =IF(C12="непродуктовый","задачи бэклога, историй нет",IF(H12>0,"истории с основным пакетом","НЕТ ИСТОРИЙ")) -> истории с основным пакетом
A13: 2.5 | B13: Подготовка демонстрационных данных | C13: продуктовый | D13: Must | E13: 22.67 | F13: В1 | G13: В1 | H13: =COUNTIF(Истории!$G$5:$G$45,A13) -> 1 | I13: =COUNTIF(Истории!$H$5:$H$45,"*"&A13&"*") -> 0 | J13: =SUMIF(Истории!$G$5:$G$45,A13,Истории!$P$5:$P$45) -> 1 | K13: =IF(C13="непродуктовый","задачи бэклога, историй нет",IF(H13>0,"истории с основным пакетом","НЕТ ИСТОРИЙ")) -> истории с основным пакетом
A14: 3.1 | B14: Реестр лошадей и карточка лошади | C14: продуктовый | D14: Must | E14: 46.33 | F14: В1 | G14: В1 | H14: =COUNTIF(Истории!$G$5:$G$45,A14) -> 3 | I14: =COUNTIF(Истории!$H$5:$H$45,"*"&A14&"*") -> 3 | J14: =SUMIF(Истории!$G$5:$G$45,A14,Истории!$P$5:$P$45) -> 1 | K14: =IF(C14="непродуктовый","задачи бэклога, историй нет",IF(H14>0,"истории с основным пакетом","НЕТ ИСТОРИЙ")) -> истории с основным пакетом
A15: 3.2 | B15: Размещение и перемещения | C15: продуктовый | D15: Must | E15: 31 | F15: В1 | G15: В2 | H15: =COUNTIF(Истории!$G$5:$G$45,A15) -> 3 | I15: =COUNTIF(Истории!$H$5:$H$45,"*"&A15&"*") -> 1 | J15: =SUMIF(Истории!$G$5:$G$45,A15,Истории!$P$5:$P$45) -> 1 | K15: =IF(C15="непродуктовый","задачи бэклога, историй нет",IF(H15>0,"истории с основным пакетом","НЕТ ИСТОРИЙ")) -> истории с основным пакетом
A16: 3.3 | B16: Ввод записей о состоянии и происшествиях | C16: продуктовый | D16: Must | E16: 20.67 | F16: В2 | G16: В2 | H16: =COUNTIF(Истории!$G$5:$G$45,A16) -> 3 | I16: =COUNTIF(Истории!$H$5:$H$45,"*"&A16&"*") -> 2 | J16: =SUMIF(Истории!$G$5:$G$45,A16,Истории!$P$5:$P$45) -> 1 | K16: =IF(C16="непродуктовый","задачи бэклога, историй нет",IF(H16>0,"истории с основным пакетом","НЕТ ИСТОРИЙ")) -> истории с основным пакетом
... A29: 6.4 | B29: Документация и приёмочные материалы | C29: непродуктовый | D29: Must | E29: 18.67 | F29: В4 | G29: В4 | H29: =COUNTIF(Истории!$G$5:$G$45,A29) -> 0 | I29: =COUNTIF(Истории!$H$5:$H$45,"*"&A29&"*") -> 0 | J29: =SUMIF(Истории!$G$5:$G$45,A29,Истории!$P$5:$P$45) -> 0 | K29: =IF(C29="непродуктовый","задачи бэклога, историй нет",IF(H29>0,"истории с основным пакетом","НЕТ ИСТОРИЙ")) -> задачи бэклога, историй нет
B30: Итого | E30: =SUM(E5:E29) -> 735.86 | H30: =SUM(H5:H29) -> 41 | J30: =SUM(J5:J29) -> 16
B31: Пакетов с историями | H31: =COUNTIF(H5:H29,">0") -> 16
B32: Пакетов без историй (непродуктовые) | H32: =COUNTIF(H5:H29,0) -> 9
B33: Проверка: историй всего на листе «Истории» | H33: =COUNTA(Истории!$A$5:$A$45) -> 41
B34: Розовым выделены пакеты, исключённые в варианте Б (запрос на изменение № 1).

Sheet Пояснения
A1: Story map продукта Stud Book: пояснения
A2: 1. Как построена карта
A3: Карта построена следующим образом: рассказали путь пользователя по шагам; сгруппировали действия по этапам (колонки карты); заполнили пробелы; расставили истории внутри этапа по приоритету (сверху вниз); разделили карту на слои по приоритету MoSCoW (Must, Should, Could), как на примере из лекции.
A4: Дополнительные требования к заданию: карта строится по всем ролям, а каждая история связана с пакетом ИСР по идентификатору. Поэтому для каждой роли собственная полоса со своими этапами пути, а в таблице есть столбцы «Основной пакет ИСР» и «Дополнительные пакеты ИСР».
A5: 2. Роли
A6: По уставу (допущение А-11) в системе две роли: клиент и сотрудник ранчо. У сотрудника два представления: «Владелец» (Дасти: реестр, записи, справки, проверка пар, очередь) и «Финансы» (Тэмми: счета, финансовая сводка). Для наглядности у каждого представления своя полоса. Ветеринар в число пользователей не входит (А-10). Отдельная полоса «Сквозные и обеспечивающие истории» собирает то, что нужно всем ролям: вход, стиль, язык, демоданные, заглушки.
A7: 3. Связь с ИСР и подсчёт освоенного объёма
A8: У каждой истории один основной пакет ИСР (по нему считается освоенный объём) и, при необходимости, дополнительные пакеты, от которых история зависит. Вес истории в пакете сейчас равен 1/N; после покера планирования его нужно заменить долей по story points. Освоенный объём пакета тогда равен сумме весов принятых историй.
A9: Из 25 пакетов ИСР 16 покрыты историями. Девять пакетов (1.1–1.4, 2.1, 2.2, 6.2–6.4) не создают функций для пользователя: по заданию фазы 4 они войдут в бэклог продукта отдельными задачами, а не историями.
A10: 4. Что нужно решить команде
A11: а) Вариант Б. В базовом плане (PERT и расписание v1.0) исключены пакеты 4.3, 5.2, 5.3 и 5.4 (запрос на изменение № 1, требует согласования с заказчиком). Их истории оставлены на карте и помечены пунктиром: 14 историй, в том числе вся полоса «Финансы» и счета клиента. Если заказчик утвердит исключение, эти истории не попадают в бэклог первой версии, а критерии приёмки 9 и 10 снимаются. Если не утвердит, расписание придётся пересчитывать.
A12: б) Вехи. В базовом плане справки (3.4, 3.5) показываются на В3, а не на В2, проверка совместимости (4.2) и кабинет клиента (5.1) на В4, а не на В3, размещение (3.2) на В2, а не на В1. Оба варианта вех указаны в таблице; для планирования итераций нужно выбрать один.
... A16: Требования Т-01…Т-15, допущения А-1…А-17, критерии приёмки и вехи: устав проекта v1.0. Пакеты ИСР и их описание: ИСР Stud Book. Приоритеты и оценки E: сводная таблица оценок. Вехи по базовому плану: расписание v1.0 и PERT. Стороны: реестр заинтересованных сторон v1.0 (соответствие Т и С взято из таблицы п. 2.2 устава).
