Workbook

Sheet Данные
A1: Исходные данные по пакетам работ
A2: Статус-дата 17.10.2026. O, M, P взяты из сводной таблицы оценок.
A4: № | B4: Пакет работ | C4: Приоритет | D4: O, ч | E4: M, ч | F4: P, ч | G4: E, ч | H4: σ, ч | I4: Готово на 17.10 | J4: E ост., ч | K4: σ ост., ч | L4: Тип | M4: Предшественницы (сводная таблица) | N4: Предшественницы (в сети) | O4: Примечание | P4: В плане Б | Q4: E ост. в плане Б, ч
A5: 1.1 | B5: Инициация проекта | C5: Must | D5: 12 | E5: 18 | F5: 28 | G5: =(D5+4*E5+F5)/6 -> 18.666667 | H5: =(F5-D5)/6 -> 2.6666667 | I5: 1 | J5: =G5*(1-I5) -> 0 | K5: =H5*(1-I5) -> 0 | L5: выполнена | M5: — | N5: — | P5: да | Q5: =IF(P5="да",J5,0) -> 0
A6: 1.2 | B6: Планирование проекта | C6: Must | D6: 20 | E6: 32 | F6: 48 | G6: =(D6+4*E6+F6)/6 -> 32.666667 | H6: =(F6-D6)/6 -> 4.6666667 | I6: 0.6 | J6: =G6*(1-I6) -> 13.066667 | K6: =H6*(1-I6) -> 1.8666667 | L6: обычная | M6: 1.1 | N6: — | O6: 1.1 выполнен | P6: да | Q6: =IF(P6="да",J6,0) -> 13.066667
A7: 1.3 | B7: Мониторинг и контроль | C7: Must | D7: 40 | E7: 60 | F7: 90 | G7: =(D7+4*E7+F7)/6 -> 61.666667 | H7: =(F7-D7)/6 -> 8.3333333 | I7: 0.37974684 | J7: =G7*(1-I7) -> 38.248945 | K7: =H7*(1-I7) -> 5.1687764 | L7: гамак | M7: 1.2 | N7: гамак | O7: идёт весь проект (гамак) | P7: да | Q7: =IF(P7="да",J7,0) -> 38.248945
A8: 1.4 | B8: Закрытие проекта | C8: Must | D8: 8 | E8: 12 | F8: 20 | G8: =(D8+4*E8+F8)/6 -> 12.666667 | H8: =(F8-D8)/6 -> 2 | I8: 0 | J8: =G8*(1-I8) -> 12.666667 | K8: =H8*(1-I8) -> 2 | L8: обычная | M8: 1.3, 6.3 | N8: 6.3 | O8: 1.3 заканчивается с началом 1.4 | P8: да | Q8: =IF(P8="да",J8,0) -> 12.666667
A9: 2.1 | B9: Сбор и анализ требований | C9: Must | D9: 16 | E9: 28 | F9: 45 | G9: =(D9+4*E9+F9)/6 -> 28.833333 | H9: =(F9-D9)/6 -> 4.8333333 | I9: 0.7 | J9: =G9*(1-I9) -> 8.65 | K9: =H9*(1-I9) -> 1.45 | L9: гамак | M9: 1.1 | N9: гамак | O9: остаток по итерациям (гамак) | P9: да | Q9: =IF(P9="да",J9,0) -> 8.65
A10: 2.2 | B10: Проектирование архитектуры и базы данных | C10: Must | D10: 18 | E10: 30 | F10: 48 | G10: =(D10+4*E10+F10)/6 -> 31 | H10: =(F10-D10)/6 -> 5 | I10: 0 | J10: =G10*(1-I10) -> 31 | K10: =H10*(1-I10) -> 5 | L10: обычная | M10: 2.1 | N10: — | O10: 2.1 в основном выполнен | P10: да | Q10: =IF(P10="да",J10,0) -> 31
A11: 2.3 | B11: Проектирование пользовательского интерфейса | C11: Must | D11: 20 | E11: 35 | F11: 55 | G11: =(D11+4*E11+F11)/6 -> 35.833333 | H11: =(F11-D11)/6 -> 5.8333333 | I11: 0 | J11: =G11*(1-I11) -> 35.833333 | K11: =H11*(1-I11) -> 5.8333333 | L11: обычная | M11: 2.1, 2.2 | N11: — | O11: параллельно с 2.2 | P11: да | Q11: =IF(P11="да",J11,0) -> 35.833333
A12: 2.4 | B12: Подготовка среды и инструментов | C12: Must | D12: 10 | E12: 16 | F12: 26 | G12: =(D12+4*E12+F12)/6 -> 16.666667 | H12: =(F12-D12)/6 -> 2.6666667 | I12: 0 | J12: =G12*(1-I12) -> 16.666667 | K12: =H12*(1-I12) -> 2.6666667 | L12: обычная | M12: 1.2 | N12: — | O12: план утверждён на статус-дату | P12: да | Q12: =IF(P12="да",J12,0) -> 16.666667
A13: 2.5 | B13: Подготовка демонстрационных данных | C13: Must | D13: 12 | E13: 22 | F13: 36 | G13: =(D13+4*E13+F13)/6 -> 22.666667 | H13: =(F13-D13)/6 -> 4 | I13: 0 | J13: =G13*(1-I13) -> 22.666667 | K13: =H13*(1-I13) -> 4 | L13: обычная | M13: 2.2, 2.4 | N13: 2.2, 2.4 | P13: да | Q13: =IF(P13="да",J13,0) -> 22.666667
A14: 3.1 | B14: Реестр лошадей и карточка лошади | C14: Must | D14: 28 | E14: 45 | F14: 70 | G14: =(D14+4*E14+F14)/6 -> 46.333333 | H14: =(F14-D14)/6 -> 7 | I14: 0 | J14: =G14*(1-I14) -> 46.333333 | K14: =H14*(1-I14) -> 7 | L14: обычная | M14: 2.2, 2.3, 2.4, 2.5 | N14: 2.2, 2.3, 2.4, 2.5, 1.2 | O14: нужны бэклог и план итерации 1 | P14: да | Q14: =IF(P14="да",J14,0) -> 46.333333
A15: 3.2 | B15: Размещение и перемещения | C15: Must | D15: 18 | E15: 30 | F15: 48 | G15: =(D15+4*E15+F15)/6 -> 31 | H15: =(F15-D15)/6 -> 5 | I15: 0 | J15: =G15*(1-I15) -> 31 | K15: =H15*(1-I15) -> 5 | L15: обычная | M15: 3.1 | N15: 3.1 | P15: да | Q15: =IF(P15="да",J15,0) -> 31
A16: 3.3 | B16: Ввод записей о состоянии и происшествиях | C16: Must | D16: 12 | E16: 20 | F16: 32 | G16: =(D16+4*E16+F16)/6 -> 20.666667 | H16: =(F16-D16)/6 -> 3.3333333 | I16: 0 | J16: =G16*(1-I16) -> 20.666667 | K16: =H16*(1-I16) -> 3.3333333 | L16: обычная | M16: 3.1, 2.3 | N16: 3.1, 2.3 | P16: да | Q16: =IF(P16="да",J16,0) -> 20.666667
A17: 3.4 | B17: Справка «История жеребца» | C17: Must | D17: 16 | E17: 26 | F17: 42 | G17: =(D17+4*E17+F17)/6 -> 27 | H17: =(F17-D17)/6 -> 4.3333333 | I17: 0 | J17: =G17*(1-I17) -> 27 | K17: =H17*(1-I17) -> 4.3333333 | L17: обычная | M17: 3.1, 3.3, 2.5 | N17: 3.1, 3.3, 2.5 | P17: да | Q17: =IF(P17="да",J17,0) -> 27
A18: 3.5 | B18: Справка «Перемещения и контакты» | C18: Must | D18: 16 | E18: 28 | F18: 45 | G18: =(D18+4*E18+F18)/6 -> 28.833333 | H18: =(F18-D18)/6 -> 4.8333333 | I18: 0 | J18: =G18*(1-I18) -> 28.833333 | K18: =H18*(1-I18) -> 4.8333333 | L18: обычная | M18: 3.2, 3.3, 2.5 | N18: 3.2, 3.3, 2.5 | P18: да | Q18: =IF(P18="да",J18,0) -> 28.833333
A19: 4.1 | B19: Формализация правил совместимости | C19: Must | D19: 8 | E19: 14 | F19: 24 | G19: =(D19+4*E19+F19)/6 -> 14.666667 | H19: =(F19-D19)/6 -> 2.6666667 | I19: 0 | J19: =G19*(1-I19) -> 14.666667 | K19: =H19*(1-I19) -> 2.6666667 | L19: обычная | M19: 2.1 | N19: — | O19: 2.1 в основном выполнен | P19: да | Q19: =IF(P19="да",J19,0) -> 14.666667
A20: 4.2 | B20: Проверка совместимости пар | C20: Must | D20: 20 | E20: 35 | F20: 55 | G20: =(D20+4*E20+F20)/6 -> 35.833333 | H20: =(F20-D20)/6 -> 5.8333333 | I20: 0 | J20: =G20*(1-I20) -> 35.833333 | K20: =H20*(1-I20) -> 5.8333333 | L20: обычная | M20: 4.1, 3.1, 2.2 | N20: 4.1, 3.1, 2.2 | P20: да | Q20: =IF(P20="да",J20,0) -> 35.833333
A21: 4.3 | B21: Очередь и календарь жеребцов | C21: Should | D21: 22 | E21: 38 | F21: 60 | G21: =(D21+4*E21+F21)/6 -> 39 | H21: =(F21-D21)/6 -> 6.3333333 | I21: 0 | J21: =G21*(1-I21) -> 39 | K21: =H21*(1-I21) -> 6.3333333 | L21: обычная | M21: 3.1, 2.2, 2.3 | N21: 3.1, 2.2, 2.3 | P21: нет | Q21: =IF(P21="да",J21,0) -> 0
A22: 5.1 | B22: Кабинет клиента и заявки | C22: Should | D22: 20 | E22: 34 | F22: 52 | G22: =(D22+4*E22+F22)/6 -> 34.666667 | H22: =(F22-D22)/6 -> 5.3333333 | I22: 0 | J22: =G22*(1-I22) -> 34.666667 | K22: =H22*(1-I22) -> 5.3333333 | L22: обычная | M22: 2.2, 2.3, 3.1 | N22: 2.2, 2.3, 3.1 | P22: да | Q22: =IF(P22="да",J22,0) -> 34.666667
A23: 5.2 | B23: Заказ семени с доставкой | C23: Should | D23: 10 | E23: 16 | F23: 26 | G23: =(D23+4*E23+F23)/6 -> 16.666667 | H23: =(F23-D23)/6 -> 2.6666667 | I23: 0 | J23: =G23*(1-I23) -> 16.666667 | K23: =H23*(1-I23) -> 2.6666667 | L23: обычная | M23: 5.1, 4.3 | N23: 5.1, 4.3 | P23: нет | Q23: =IF(P23="да",J23,0) -> 0
A24: 5.3 | B24: Счета и платежи | C24: Should | D24: 18 | E24: 30 | F24: 48 | G24: =(D24+4*E24+F24)/6 -> 31 | H24: =(F24-D24)/6 -> 5 | I24: 0 | J24: =G24*(1-I24) -> 31 | K24: =H24*(1-I24) -> 5 | L24: обычная | M24: 5.1, 4.3, 3.1 | N24: 5.1, 4.3, 3.1 | P24: нет | Q24: =IF(P24="да",J24,0) -> 0
A25: 5.4 | B25: Отчёты и напоминания (Could) | C25: Could | D25: 12 | E25: 20 | F25: 32 | G25: =(D25+4*E25+F25)/6 -> 20.666667 | H25: =(F25-D25)/6 -> 3.3333333 | I25: 0 | J25: =G25*(1-I25) -> 20.666667 | K25: =H25*(1-I25) -> 3.3333333 | L25: обычная | M25: 3.1, 4.3, 5.3 | N25: 3.1, 4.3, 5.3 | P25: нет | Q25: =IF(P25="да",J25,0) -> 0
A26: 6.1 | B26: Интеграция внешних сервисов (заглушки) | C26: Must | D26: 16 | E26: 28 | F26: 45 | G26: =(D26+4*E26+F26)/6 -> 28.833333 | H26: =(F26-D26)/6 -> 4.8333333 | I26: 0 | J26: =G26*(1-I26) -> 28.833333 | K26: =H26*(1-I26) -> 4.8333333 | L26: обычная | M26: 2.2, 2.4 | N26: 2.2, 2.4 | P26: да | Q26: =IF(P26="да",J26,0) -> 28.833333
A27: 6.2 | B27: Тестирование и исправление дефектов | C27: Must | D27: 35 | E27: 55 | F27: 85 | G27: =(D27+4*E27+F27)/6 -> 56.666667 | H27: =(F27-D27)/6 -> 8.3333333 | I27: 0 | J27: =G27*(1-I27) -> 56.666667 | K27: =H27*(1-I27) -> 8.3333333 | L27: гамак | M27: 3.1–5.3 (по итерациям) | N27: гамак | O27: с начала 3.1 до начала 6.3 (гамак) | P27: да | Q27: =IF(P27="да",J27,0) -> 56.666667
A28: 6.3 | B28: Демонстрации и приёмка | C28: Must | D28: 16 | E28: 24 | F28: 36 | G28: =(D28+4*E28+F28)/6 -> 24.666667 | H28: =(F28-D28)/6 -> 3.3333333 | I28: 0 | J28: =G28*(1-I28) -> 24.666667 | K28: =H28*(1-I28) -> 3.3333333 | L28: обычная | M28: 6.2 (по итерациям) | N28: 4.2, 5.1, 6.1, 6.4 | O28: после всех сдаваемых пакетов | P28: да | Q28: =IF(P28="да",J28,0) -> 24.666667
A29: 6.4 | B29: Документация и приёмочные материалы | C29: Must | D29: 12 | E29: 18 | F29: 28 | G29: =(D29+4*E29+F29)/6 -> 18.666667 | H29: =(F29-D29)/6 -> 2.6666667 | I29: 0 | J29: =G29*(1-I29) -> 18.666667 | K29: =H29*(1-I29) -> 2.6666667 | L29: обычная | M29: 1.3, 6.3 | N29: 3.4, 3.5 | O29: руководство нужно до приёмки (критерий 15) | P29: да | Q29: =IF(P29="да",J29,0) -> 18.666667
B30: Итого | D30: =SUM(D5:D29) -> 435 | E30: =SUM(E5:E29) -> 714 | F30: =SUM(F5:F29) -> 1124 | G30: =SUM(G5:G29) -> 735.83333 | J30: =SUM(J5:J29) -> 653.96561 | Q30: =SUM(Q5:Q29) -> 546.63228

Sheet PERT (вариант А)
A1: Расчёт сети. Вариант А: все пакеты, 54 ч/нед
A2: Сроки в рабочих днях от 19.10.2026.
A4: № | B4: Пакет работ | C4: Тип | D4: E ост., ч | E4: σ ост., ч | F4: Исполнители | G4: Мощность, ч/дн | H4: D, дн | I4: σ, дн | J4: ES | K4: EF | L4: LS | M4: LF | N4: Rполн | O4: Rсвоб | P4: Rнез | Q4: Крит.
A5: 1.1 | B5: Инициация проекта | C5: выполнена | D5: ='Данные'!J5 -> 0 | E5: ='Данные'!K5 -> 0 | F5: — | G5: — | H5: — | I5: — | J5: — | K5: — | L5: — | M5: — | N5: — | O5: — | P5: — | Q5: —
A6: 1.2 | B6: Планирование проекта | C6: обычная | D6: ='Данные'!J6 -> 13.066667 | E6: ='Данные'!K6 -> 1.8666667 | F6: PM, TW | G6: 1.8 | H6: =D6/G6 -> 7.2592593 | I6: =E6/G6 -> 1.037037 | J6: =0 -> 0 | K6: =J6+H6 -> 7.2592593 | L6: =ROUND(M6-H6,9) -> 8.3197316 | M6: =MIN(L14) -> 15.578991 | N6: =ROUND(L6-J6,6) -> 8.319732 | O6: =ROUND(MIN(J14)-K6,6) -> 8.319732 | P6: =ROUND(MAX(0,MIN(J14)-0-H6),6) -> 8.319732 | Q6: =IF(ABS(N6)<0.000001,"да","")
A7: 1.3 | B7: Мониторинг и контроль | C7: гамак | D7: ='Данные'!J7 -> 38.248945 | E7: ='Данные'!K7 -> 5.1687764 | F7: PM | G7: — | H7: =K7-J7 -> 54.801556 | I7: — | J7: =0 -> 0 | K7: =J8 -> 54.801556 | L7: — | M7: — | N7: — | O7: — | P7: — | Q7: —
A8: 1.4 | B8: Закрытие проекта | C8: обычная | D8: ='Данные'!J8 -> 12.666667 | E8: ='Данные'!K8 -> 2 | F8: PM, TW | G8: 3.2 | H8: =D8/G8 -> 3.9583333 | I8: =E8/G8 -> 0.625 | J8: =MAX(K28) -> 54.801556 | K8: =J8+H8 -> 58.759889 | L8: =ROUND(M8-H8,9) -> 54.801556 | M8: =K8 -> 58.759889 | N8: =ROUND(L8-J8,6) -> 0 | O8: =ROUND(M8-K8,6) -> 0 | P8: =ROUND(MAX(0,M8-MAX(M28)-H8),6) -> 0 | Q8: =IF(ABS(N8)<0.000001,"да","") -> да
A9: 2.1 | B9: Сбор и анализ требований | C9: гамак | D9: ='Данные'!J9 -> 8.65 | E9: ='Данные'!K9 -> 1.45 | F9: BA | G9: — | H9: =K9-J9 -> 54.801556 | I9: — | J9: =0 -> 0 | K9: =J8 -> 54.801556 | L9: — | M9: — | N9: — | O9: — | P9: — | Q9: —
A10: 2.2 | B10: Проектирование архитектуры и базы данных | C10: обычная | D10: ='Данные'!J10 -> 31 | E10: ='Данные'!K10 -> 5 | F10: BE, BA | G10: 2.6 | H10: =D10/G10 -> 11.923077 | I10: =E10/G10 -> 1.9230769 | J10: =0 -> 0 | K10: =J10+H10 -> 11.923077 | L10: =ROUND(M10-H10,9) -> 0 | M10: =MIN(L13,L14,L20,L21,L22,L26) -> 11.923077 | N10: =ROUND(L10-J10,6) -> 0 | O10: =ROUND(MIN(J13,J14,J20,J21,J22,J26)-K10,6) -> 0 | P10: =ROUND(MAX(0,MIN(J13,J14,J20,J21,J22,J26)-0-H10),6) -> 0 | Q10: =IF(ABS(N10)<0.000001,"да","") -> да
A11: 2.3 | B11: Проектирование пользовательского интерфейса | C11: обычная | D11: ='Данные'!J11 -> 35.833333 | E11: ='Данные'!K11 -> 5.8333333 | F11: UX1, UX2 | G11: 3.6 | H11: =D11/G11 -> 9.9537037 | I11: =E11/G11 -> 1.6203704 | J11: =0 -> 0 | K11: =J11+H11 -> 9.9537037 | L11: =ROUND(M11-H11,9) -> 5.6252872 | M11: =MIN(L14,L16,L21,L22) -> 15.578991 | N11: =ROUND(L11-J11,6) -> 5.625287 | O11: =ROUND(MIN(J14,J16,J21,J22)-K11,6) -> 5.625287 | P11: =ROUND(MAX(0,MIN(J14,J16,J21,J22)-0-H11),6) -> 5.625287 | Q11: =IF(ABS(N11)<0.000001,"да","")
A12: 2.4 | B12: Подготовка среды и инструментов | C12: обычная | D12: ='Данные'!J12 -> 16.666667 | E12: ='Данные'!K12 -> 2.6666667 | F12: PM, QA, TW | G12: 3 | H12: =D12/G12 -> 5.5555556 | I12: =E12/G12 -> 0.88888889 | J12: =0 -> 0 | K12: =J12+H12 -> 5.5555556 | L12: =ROUND(M12-H12,9) -> 6.3675214 | M12: =MIN(L13,L14,L26) -> 11.923077 | N12: =ROUND(L12-J12,6) -> 6.367521 | O12: =ROUND(MIN(J13,J14,J26)-K12,6) -> 6.367521 | P12: =ROUND(MAX(0,MIN(J13,J14,J26)-0-H12),6) -> 6.367521 | Q12: =IF(ABS(N12)<0.000001,"да","")
A13: 2.5 | B13: Подготовка демонстрационных данных | C13: обычная | D13: ='Данные'!J13 -> 22.666667 | E13: ='Данные'!K13 -> 4 | F13: BA, QA, UX1, UX2 | G13: 6.2 | H13: =D13/G13 -> 3.655914 | I13: =E13/G13 -> 0.64516129 | J13: =MAX(K10,K12) -> 11.923077 | K13: =J13+H13 -> 15.578991 | L13: =ROUND(M13-H13,9) -> 11.923077 | M13: =MIN(L14,L17,L18) -> 15.578991 | N13: =ROUND(L13-J13,6) -> 0 | O13: =ROUND(MIN(J14,J17,J18)-K13,6) -> 0 | P13: =ROUND(MAX(0,MIN(J14,J17,J18)-MAX(M10,M12)-H13),6) -> 0 | Q13: =IF(ABS(N13)<0.000001,"да","") -> да
A14: 3.1 | B14: Реестр лошадей и карточка лошади | C14: обычная | D14: ='Данные'!J14 -> 46.333333 | E14: ='Данные'!K14 -> 7 | F14: BE, BA, UX1, UX2 | G14: 6.2 | H14: =D14/G14 -> 7.4731183 | I14: =E14/G14 -> 1.1290323 | J14: =MAX(K10,K11,K12,K13,K6) -> 15.578991 | K14: =J14+H14 -> 23.052109 | L14: =ROUND(M14-H14,9) -> 15.578991 | M14: =MIN(L15,L16,L17,L20,L21,L22,L24,L25) -> 23.052109 | N14: =ROUND(L14-J14,6) -> 0 | O14: =ROUND(MIN(J15,J16,J17,J20,J21,J22,J24,J25)-K14,6) -> 0 | P14: =ROUND(MAX(0,MIN(J15,J16,J17,J20,J21,J22,J24,J25)-MAX(M10,M11,M12,M13,M6)-H14),6) -> 0 | Q14: =IF(ABS(N14)<0.000001,"да","") -> да
A15: 3.2 | B15: Размещение и перемещения | C15: обычная | D15: ='Данные'!J15 -> 31 | E15: ='Данные'!K15 -> 5 | F15: BE, UX1 | G15: 3.2 | H15: =D15/G15 -> 9.6875 | I15: =E15/G15 -> 1.5625 | J15: =MAX(K14) -> 23.052109 | K15: =J15+H15 -> 32.739609 | L15: =ROUND(M15-H15,9) -> 23.052109 | M15: =MIN(L18) -> 32.739609 | N15: =ROUND(L15-J15,6) -> 0 | O15: =ROUND(MIN(J18)-K15,6) -> 0 | P15: =ROUND(MAX(0,MIN(J18)-MAX(M14)-H15),6) -> 0 | Q15: =IF(ABS(N15)<0.000001,"да","") -> да
A16: 3.3 | B16: Ввод записей о состоянии и происшествиях | C16: обычная | D16: ='Данные'!J16 -> 20.666667 | E16: ='Данные'!K16 -> 3.3333333 | F16: BA, UX2 | G16: 3 | H16: =D16/G16 -> 6.8888889 | I16: =E16/G16 -> 1.1111111 | J16: =MAX(K14,K11) -> 23.052109 | K16: =J16+H16 -> 29.940998 | L16: =ROUND(M16-H16,9) -> 25.85072 | M16: =MIN(L17,L18) -> 32.739609 | N16: =ROUND(L16-J16,6) -> 2.798611 | O16: =ROUND(MIN(J17,J18)-K16,6) -> 0 | P16: =ROUND(MAX(0,MIN(J17,J18)-MAX(M14,M11)-H16),6) -> 0 | Q16: =IF(ABS(N16)<0.000001,"да","")
A17: 3.4 | B17: Справка «История жеребца» | C17: обычная | D17: ='Данные'!J17 -> 27 | E17: ='Данные'!K17 -> 4.3333333 | F17: BA, UX2 | G17: 3 | H17: =D17/G17 -> 9 | I17: =E17/G17 -> 1.4444444 | J17: =MAX(K14,K16,K13) -> 29.940998 | K17: =J17+H17 -> 38.940998 | L17: =ROUND(M17-H17,9) -> 32.750026 | M17: =MIN(L29) -> 41.750026 | N17: =ROUND(L17-J17,6) -> 2.809028 | O17: =ROUND(MIN(J29)-K17,6) -> 2.809028 | P17: =ROUND(MAX(0,MIN(J29)-MAX(M14,M16,M13)-H17),6) -> 0.010417 | Q17: =IF(ABS(N17)<0.000001,"да","")
A18: 3.5 | B18: Справка «Перемещения и контакты» | C18: обычная | D18: ='Данные'!J18 -> 28.833333 | E18: ='Данные'!K18 -> 4.8333333 | F18: BE, UX1 | G18: 3.2 | H18: =D18/G18 -> 9.0104167 | I18: =E18/G18 -> 1.5104167 | J18: =MAX(K15,K16,K13) -> 32.739609 | K18: =J18+H18 -> 41.750026 | L18: =ROUND(M18-H18,9) -> 32.739609 | M18: =MIN(L29) -> 41.750026 | N18: =ROUND(L18-J18,6) -> 0 | O18: =ROUND(MIN(J29)-K18,6) -> 0 | P18: =ROUND(MAX(0,MIN(J29)-MAX(M15,M16,M13)-H18),6) -> 0 | Q18: =IF(ABS(N18)<0.000001,"да","") -> да
A19: 4.1 | B19: Формализация правил совместимости | C19: обычная | D19: ='Данные'!J19 -> 14.666667 | E19: ='Данные'!K19 -> 2.6666667 | F19: PM, TW | G19: 1.8 | H19: =D19/G19 -> 8.1481481 | I19: =E19/G19 -> 1.4814815 | J19: =0 -> 0 | K19: =J19+H19 -> 8.1481481 | L19: =ROUND(M19-H19,9) -> 32.774331 | M19: =MIN(L20) -> 40.92248 | N19: =ROUND(L19-J19,6) -> 32.774331 | O19: =ROUND(MIN(J20)-K19,6) -> 14.903961 | P19: =ROUND(MAX(0,MIN(J20)-0-H19),6) -> 14.903961 | Q19: =IF(ABS(N19)<0.000001,"да","")
A20: 4.2 | B20: Проверка совместимости пар | C20: обычная | D20: ='Данные'!J20 -> 35.833333 | E20: ='Данные'!K20 -> 5.8333333 | F20: BE, UX1 | G20: 3.2 | H20: =D20/G20 -> 11.197917 | I20: =E20/G20 -> 1.8229167 | J20: =MAX(K19,K14,K10) -> 23.052109 | K20: =J20+H20 -> 34.250026 | L20: =ROUND(M20-H20,9) -> 40.92248 | M20: =MIN(L28) -> 52.120396 | N20: =ROUND(L20-J20,6) -> 17.87037 | O20: =ROUND(MIN(J28)-K20,6) -> 17.87037 | P20: =ROUND(MAX(0,MIN(J28)-MAX(M19,M14,M10)-H20),6) -> 0 | Q20: =IF(ABS(N20)<0.000001,"да","")
A21: 4.3 | B21: Очередь и календарь жеребцов | C21: обычная | D21: ='Данные'!J21 -> 39 | E21: ='Данные'!K21 -> 6.3333333 | F21: BE, UX1 | G21: 3.2 | H21: =D21/G21 -> 12.1875 | I21: =E21/G21 -> 1.9791667 | J21: =MAX(K14,K10,K11) -> 23.052109 | K21: =J21+H21 -> 35.239609 | L21: =ROUND(M21-H21,9) -> 23.356507 | M21: =MIN(L23,L24,L25) -> 35.544007 | N21: =ROUND(L21-J21,6) -> 0.304398 | O21: =ROUND(MIN(J23,J24,J25)-K21,6) -> 0 | P21: =ROUND(MAX(0,MIN(J23,J24,J25)-MAX(M14,M10,M11)-H21),6) -> 0 | Q21: =IF(ABS(N21)<0.000001,"да","")
A22: 5.1 | B22: Кабинет клиента и заявки | C22: обычная | D22: ='Данные'!J22 -> 34.666667 | E22: ='Данные'!K22 -> 5.3333333 | F22: BA, UX2 | G22: 3 | H22: =D22/G22 -> 11.555556 | I22: =E22/G22 -> 1.7777778 | J22: =MAX(K10,K11,K14) -> 23.052109 | K22: =J22+H22 -> 34.607665 | L22: =ROUND(M22-H22,9) -> 23.988452 | M22: =MIN(L23,L24) -> 35.544007 | N22: =ROUND(L22-J22,6) -> 0.936343 | O22: =ROUND(MIN(J23,J24)-K22,6) -> 0.631944 | P22: =ROUND(MAX(0,MIN(J23,J24)-MAX(M10,M11,M14)-H22),6) -> 0.631944 | Q22: =IF(ABS(N22)<0.000001,"да","")
A23: 5.2 | B23: Заказ семени с доставкой | C23: обычная | D23: ='Данные'!J23 -> 16.666667 | E23: ='Данные'!K23 -> 2.6666667 | F23: BA, UX2 | G23: 3 | H23: =D23/G23 -> 5.5555556 | I23: =E23/G23 -> 0.88888889 | J23: =MAX(K22,K21) -> 35.239609 | K23: =J23+H23 -> 40.795165 | L23: =ROUND(M23-H23,9) -> 46.564841 | M23: =MIN(L28) -> 52.120396 | N23: =ROUND(L23-J23,6) -> 11.325231 | O23: =ROUND(MIN(J28)-K23,6) -> 11.325231 | P23: =ROUND(MAX(0,MIN(J28)-MAX(M22,M21)-H23),6) -> 11.020833 | Q23: =IF(ABS(N23)<0.000001,"да","")
A24: 5.3 | B24: Счета и платежи | C24: обычная | D24: ='Данные'!J24 -> 31 | E24: ='Данные'!K24 -> 5 | F24: BE, UX1 | G24: 3.2 | H24: =D24/G24 -> 9.6875 | I24: =E24/G24 -> 1.5625 | J24: =MAX(K22,K21,K14) -> 35.239609 | K24: =J24+H24 -> 44.927109 | L24: =ROUND(M24-H24,9) -> 35.544007 | M24: =MIN(L25) -> 45.231507 | N24: =ROUND(L24-J24,6) -> 0.304398 | O24: =ROUND(MIN(J25)-K24,6) -> 0 | P24: =ROUND(MAX(0,MIN(J25)-MAX(M22,M21,M14)-H24),6) -> 0 | Q24: =IF(ABS(N24)<0.000001,"да","")
A25: 5.4 | B25: Отчёты и напоминания (Could) | C25: обычная | D25: ='Данные'!J25 -> 20.666667 | E25: ='Данные'!K25 -> 3.3333333 | F25: BA, UX2 | G25: 3 | H25: =D25/G25 -> 6.8888889 | I25: =E25/G25 -> 1.1111111 | J25: =MAX(K14,K21,K24) -> 44.927109 | K25: =J25+H25 -> 51.815998 | L25: =ROUND(M25-H25,9) -> 45.231507 | M25: =MIN(L28) -> 52.120396 | N25: =ROUND(L25-J25,6) -> 0.304398 | O25: =ROUND(MIN(J28)-K25,6) -> 0.304398 | P25: =ROUND(MAX(0,MIN(J28)-MAX(M14,M21,M24)-H25),6) -> 0 | Q25: =IF(ABS(N25)<0.000001,"да","")
A26: 6.1 | B26: Интеграция внешних сервисов (заглушки) | C26: обычная | D26: ='Данные'!J26 -> 28.833333 | E26: ='Данные'!K26 -> 4.8333333 | F26: PM, TW | G26: 1.8 | H26: =D26/G26 -> 16.018519 | I26: =E26/G26 -> 2.6851852 | J26: =MAX(K10,K12) -> 11.923077 | K26: =J26+H26 -> 27.941595 | L26: =ROUND(M26-H26,9) -> 36.101878 | M26: =MIN(L28) -> 52.120396 | N26: =ROUND(L26-J26,6) -> 24.178801 | O26: =ROUND(MIN(J28)-K26,6) -> 24.178801 | P26: =ROUND(MAX(0,MIN(J28)-MAX(M10,M12)-H26),6) -> 24.178801 | Q26: =IF(ABS(N26)<0.000001,"да","")
A27: 6.2 | B27: Тестирование и исправление дефектов | C27: гамак | D27: ='Данные'!J27 -> 56.666667 | E27: ='Данные'!K27 -> 8.3333333 | F27: QA, TW | G27: — | H27: =K27-J27 -> 36.541405 | I27: — | J27: =J14 -> 15.578991 | K27: =J28 -> 52.120396 | L27: — | M27: — | N27: — | O27: — | P27: — | Q27: —
A28: 6.3 | B28: Демонстрации и приёмка | C28: обычная | D28: ='Данные'!J28 -> 24.666667 | E28: ='Данные'!K28 -> 3.3333333 | F28: PM, BA, UX1, UX2, QA, TW, BE | G28: 9.2 | H28: =D28/G28 -> 2.6811594 | I28: =E28/G28 -> 0.36231884 | J28: =MAX(K20,K23,K25,K26,K29) -> 52.120396 | K28: =J28+H28 -> 54.801556 | L28: =ROUND(M28-H28,9) -> 52.120396 | M28: =MIN(L8) -> 54.801556 | N28: =ROUND(L28-J28,6) -> 0 | O28: =ROUND(MIN(J8)-K28,6) -> 0 | P28: =ROUND(MAX(0,MIN(J8)-MAX(M20,M23,M25,M26,M29)-H28),6) -> 0 | Q28: =IF(ABS(N28)<0.000001,"да","") -> да
A29: 6.4 | B29: Документация и приёмочные материалы | C29: обычная | D29: ='Данные'!J29 -> 18.666667 | E29: ='Данные'!K29 -> 2.6666667 | F29: TW, PM | G29: 1.8 | H29: =D29/G29 -> 10.37037 | I29: =E29/G29 -> 1.4814815 | J29: =MAX(K17,K18) -> 41.750026 | K29: =J29+H29 -> 52.120396 | L29: =ROUND(M29-H29,9) -> 41.750026 | M29: =MIN(L28) -> 52.120396 | N29: =ROUND(L29-J29,6) -> 0 | O29: =ROUND(MIN(J28)-K29,6) -> 0 | P29: =ROUND(MAX(0,MIN(J28)-MAX(M17,M18)-H29),6) -> 0 | Q29: =IF(ABS(N29)<0.000001,"да","") -> да
B31: Tкр (окончание финальной приёмки 6.3), раб. дн | D31: =K28 -> 54.801556
B32: Окончание проекта (1.4), раб. дн | D32: =K8 -> 58.759889
B33: Tдир (25.12.2026), раб. дн | D33: 49
B34: Критический путь: 2.2 → 2.5 → 3.1 → 3.2 → 3.5 → 6.4 → 6.3 → 1.4
B36: D = E ост. / мощность; σ (дн) = σ ост. (ч) / мощность. ES = max EF предшественниц; EF = ES + D; LF = min LS последователей; LS = LF − D.
B37: Rполн = LS − ES; Rсвоб = min ES последователей − EF; Rнез = max(0; min ES последователей − max LF предшественниц − D).
B38: Гамак — растянутая работа: длительность берётся из сети, резервы не считаются.

Sheet PERT (вариант Б)
A1: Расчёт сети. Вариант Б: базовый план, 68 ч/нед
A2: Сроки в рабочих днях от 19.10.2026.
A4: № | B4: Пакет работ | C4: Тип | D4: E ост., ч | E4: σ ост., ч | F4: Исполнители | G4: Мощность, ч/дн | H4: D, дн | I4: σ, дн | J4: ES | K4: EF | L4: LS | M4: LF | N4: Rполн | O4: Rсвоб | P4: Rнез | Q4: Крит.
A5: 1.1 | B5: Инициация проекта | C5: выполнена | D5: ='Данные'!J5 -> 0 | E5: ='Данные'!K5 -> 0 | F5: — | G5: — | H5: — | I5: — | J5: — | K5: — | L5: — | M5: — | N5: — | O5: — | P5: — | Q5: —
A6: 1.2 | B6: Планирование проекта | C6: обычная | D6: ='Данные'!J6 -> 13.066667 | E6: ='Данные'!K6 -> 1.8666667 | F6: PM, TW | G6: 2.8 | H6: =D6/G6 -> 4.6666667 | I6: =E6/G6 -> 0.66666667 | J6: =0 -> 0 | K6: =J6+H6 -> 4.6666667 | L6: =ROUND(M6-H6,9) -> 7.3569633 | M6: =MIN(L14) -> 12.02363 | N6: =ROUND(L6-J6,6) -> 7.356963 | O6: =ROUND(MIN(J14)-K6,6) -> 7.356963 | P6: =ROUND(MAX(0,MIN(J14)-0-H6),6) -> 7.356963 | Q6: =IF(ABS(N6)<0.000001,"да","")
A7: 1.3 | B7: Мониторинг и контроль | C7: гамак | D7: ='Данные'!J7 -> 38.248945 | E7: ='Данные'!K7 -> 5.1687764 | F7: PM | G7: — | H7: =K7-J7 -> 41.610659 | I7: — | J7: =0 -> 0 | K7: =J8 -> 41.610659 | L7: — | M7: — | N7: — | O7: — | P7: — | Q7: —
A8: 1.4 | B8: Закрытие проекта | C8: обычная | D8: ='Данные'!J8 -> 12.666667 | E8: ='Данные'!K8 -> 2 | F8: PM, TW | G8: 4 | H8: =D8/G8 -> 3.1666667 | I8: =E8/G8 -> 0.5 | J8: =MAX(K28) -> 41.610659 | K8: =J8+H8 -> 44.777325 | L8: =ROUND(M8-H8,9) -> 41.610659 | M8: =K8 -> 44.777325 | N8: =ROUND(L8-J8,6) -> 0 | O8: =ROUND(M8-K8,6) -> 0 | P8: =ROUND(MAX(0,M8-MAX(M28)-H8),6) -> 0 | Q8: =IF(ABS(N8)<0.000001,"да","") -> да
A9: 2.1 | B9: Сбор и анализ требований | C9: гамак | D9: ='Данные'!J9 -> 8.65 | E9: ='Данные'!K9 -> 1.45 | F9: BA | G9: — | H9: =K9-J9 -> 41.610659 | I9: — | J9: =0 -> 0 | K9: =J8 -> 41.610659 | L9: — | M9: — | N9: — | O9: — | P9: — | Q9: —
A10: 2.2 | B10: Проектирование архитектуры и базы данных | C10: обычная | D10: ='Данные'!J10 -> 31 | E10: ='Данные'!K10 -> 5 | F10: BE, BA | G10: 3.4 | H10: =D10/G10 -> 9.1176471 | I10: =E10/G10 -> 1.4705882 | J10: =0 -> 0 | K10: =J10+H10 -> 9.1176471 | L10: =ROUND(M10-H10,9) -> 0 | M10: =MIN(L13,L14,L20,L22,L26) -> 9.1176471 | N10: =ROUND(L10-J10,6) -> 0 | O10: =ROUND(MIN(J13,J14,J20,J22,J26)-K10,6) -> 0 | P10: =ROUND(MAX(0,MIN(J13,J14,J20,J22,J26)-0-H10),6) -> 0 | Q10: =IF(ABS(N10)<0.000001,"да","") -> да
A11: 2.3 | B11: Проектирование пользовательского интерфейса | C11: обычная | D11: ='Данные'!J11 -> 35.833333 | E11: ='Данные'!K11 -> 5.8333333 | F11: UX1, UX2 | G11: 4.4 | H11: =D11/G11 -> 8.1439394 | I11: =E11/G11 -> 1.3257576 | J11: =0 -> 0 | K11: =J11+H11 -> 8.1439394 | L11: =ROUND(M11-H11,9) -> 3.8796906 | M11: =MIN(L14,L16,L22) -> 12.02363 | N11: =ROUND(L11-J11,6) -> 3.879691 | O11: =ROUND(MIN(J14,J16,J22)-K11,6) -> 3.879691 | P11: =ROUND(MAX(0,MIN(J14,J16,J22)-0-H11),6) -> 3.879691 | Q11: =IF(ABS(N11)<0.000001,"да","")
A12: 2.4 | B12: Подготовка среды и инструментов | C12: обычная | D12: ='Данные'!J12 -> 16.666667 | E12: ='Данные'!K12 -> 2.6666667 | F12: PM, QA, TW | G12: 4.4 | H12: =D12/G12 -> 3.7878788 | I12: =E12/G12 -> 0.60606061 | J12: =0 -> 0 | K12: =J12+H12 -> 3.7878788 | L12: =ROUND(M12-H12,9) -> 5.3297683 | M12: =MIN(L13,L14,L26) -> 9.1176471 | N12: =ROUND(L12-J12,6) -> 5.329768 | O12: =ROUND(MIN(J13,J14,J26)-K12,6) -> 5.329768 | P12: =ROUND(MAX(0,MIN(J13,J14,J26)-0-H12),6) -> 5.329768 | Q12: =IF(ABS(N12)<0.000001,"да","")
A13: 2.5 | B13: Подготовка демонстрационных данных | C13: обычная | D13: ='Данные'!J13 -> 22.666667 | E13: ='Данные'!K13 -> 4 | F13: BA, QA, UX1, UX2 | G13: 7.8 | H13: =D13/G13 -> 2.9059829 | I13: =E13/G13 -> 0.51282051 | J13: =MAX(K10,K12) -> 9.1176471 | K13: =J13+H13 -> 12.02363 | L13: =ROUND(M13-H13,9) -> 9.1176471 | M13: =MIN(L14,L17,L18) -> 12.02363 | N13: =ROUND(L13-J13,6) -> 0 | O13: =ROUND(MIN(J14,J17,J18)-K13,6) -> 0 | P13: =ROUND(MAX(0,MIN(J14,J17,J18)-MAX(M10,M12)-H13),6) -> 0 | Q13: =IF(ABS(N13)<0.000001,"да","") -> да
A14: 3.1 | B14: Реестр лошадей и карточка лошади | C14: обычная | D14: ='Данные'!J14 -> 46.333333 | E14: ='Данные'!K14 -> 7 | F14: BE, BA, UX1, UX2 | G14: 7.8 | H14: =D14/G14 -> 5.9401709 | I14: =E14/G14 -> 0.8974359 | J14: =MAX(K10,K11,K12,K13,K6) -> 12.02363 | K14: =J14+H14 -> 17.963801 | L14: =ROUND(M14-H14,9) -> 12.02363 | M14: =MIN(L15,L16,L17,L20,L22) -> 17.963801 | N14: =ROUND(L14-J14,6) -> 0 | O14: =ROUND(MIN(J15,J16,J17,J20,J22)-K14,6) -> 0 | P14: =ROUND(MAX(0,MIN(J15,J16,J17,J20,J22)-MAX(M10,M11,M12,M13,M6)-H14),6) -> 0 | Q14: =IF(ABS(N14)<0.000001,"да","") -> да
A15: 3.2 | B15: Размещение и перемещения | C15: обычная | D15: ='Данные'!J15 -> 31 | E15: ='Данные'!K15 -> 5 | F15: BE, UX1 | G15: 4 | H15: =D15/G15 -> 7.75 | I15: =E15/G15 -> 1.25 | J15: =MAX(K14) -> 17.963801 | K15: =J15+H15 -> 25.713801 | L15: =ROUND(M15-H15,9) -> 17.963801 | M15: =MIN(L18) -> 25.713801 | N15: =ROUND(L15-J15,6) -> 0 | O15: =ROUND(MIN(J18)-K15,6) -> 0 | P15: =ROUND(MAX(0,MIN(J18)-MAX(M14)-H15),6) -> 0 | Q15: =IF(ABS(N15)<0.000001,"да","") -> да
A16: 3.3 | B16: Ввод записей о состоянии и происшествиях | C16: обычная | D16: ='Данные'!J16 -> 20.666667 | E16: ='Данные'!K16 -> 3.3333333 | F16: BA, UX2 | G16: 3.8 | H16: =D16/G16 -> 5.4385965 | I16: =E16/G16 -> 0.87719298 | J16: =MAX(K14,K11) -> 17.963801 | K16: =J16+H16 -> 23.402397 | L16: =ROUND(M16-H16,9) -> 20.275204 | M16: =MIN(L17,L18) -> 25.713801 | N16: =ROUND(L16-J16,6) -> 2.311404 | O16: =ROUND(MIN(J17,J18)-K16,6) -> 0 | P16: =ROUND(MAX(0,MIN(J17,J18)-MAX(M14,M11)-H16),6) -> 0 | Q16: =IF(ABS(N16)<0.000001,"да","")
A17: 3.4 | B17: Справка «История жеребца» | C17: обычная | D17: ='Данные'!J17 -> 27 | E17: ='Данные'!K17 -> 4.3333333 | F17: BA, UX2 | G17: 3.8 | H17: =D17/G17 -> 7.1052632 | I17: =E17/G17 -> 1.1403509 | J17: =MAX(K14,K16,K13) -> 23.402397 | K17: =J17+H17 -> 30.507661 | L17: =ROUND(M17-H17,9) -> 25.816871 | M17: =MIN(L29) -> 32.922134 | N17: =ROUND(L17-J17,6) -> 2.414474 | O17: =ROUND(MIN(J29)-K17,6) -> 2.414474 | P17: =ROUND(MAX(0,MIN(J29)-MAX(M14,M16,M13)-H17),6) -> 0.10307 | Q17: =IF(ABS(N17)<0.000001,"да","")
A18: 3.5 | B18: Справка «Перемещения и контакты» | C18: обычная | D18: ='Данные'!J18 -> 28.833333 | E18: ='Данные'!K18 -> 4.8333333 | F18: BE, UX1 | G18: 4 | H18: =D18/G18 -> 7.2083333 | I18: =E18/G18 -> 1.2083333 | J18: =MAX(K15,K16,K13) -> 25.713801 | K18: =J18+H18 -> 32.922134 | L18: =ROUND(M18-H18,9) -> 25.713801 | M18: =MIN(L29) -> 32.922134 | N18: =ROUND(L18-J18,6) -> 0 | O18: =ROUND(MIN(J29)-K18,6) -> 0 | P18: =ROUND(MAX(0,MIN(J29)-MAX(M15,M16,M13)-H18),6) -> 0 | Q18: =IF(ABS(N18)<0.000001,"да","") -> да
A19: 4.1 | B19: Формализация правил совместимости | C19: обычная | D19: ='Данные'!J19 -> 14.666667 | E19: ='Данные'!K19 -> 2.6666667 | F19: PM, TW | G19: 2.8 | H19: =D19/G19 -> 5.2380952 | I19: =E19/G19 -> 0.95238095 | J19: =0 -> 0 | K19: =J19+H19 -> 5.2380952 | L19: =ROUND(M19-H19,9) -> 25.392372 | M19: =MIN(L20) -> 30.630468 | N19: =ROUND(L19-J19,6) -> 25.392372 | O19: =ROUND(MIN(J20)-K19,6) -> 12.725706 | P19: =ROUND(MAX(0,MIN(J20)-0-H19),6) -> 12.725706 | Q19: =IF(ABS(N19)<0.000001,"да","")
A20: 4.2 | B20: Проверка совместимости пар | C20: обычная | D20: ='Данные'!J20 -> 35.833333 | E20: ='Данные'!K20 -> 5.8333333 | F20: BE, UX1 | G20: 4 | H20: =D20/G20 -> 8.9583333 | I20: =E20/G20 -> 1.4583333 | J20: =MAX(K19,K14,K10) -> 17.963801 | K20: =J20+H20 -> 26.922134 | L20: =ROUND(M20-H20,9) -> 30.630468 | M20: =MIN(L28) -> 39.588801 | N20: =ROUND(L20-J20,6) -> 12.666667 | O20: =ROUND(MIN(J28)-K20,6) -> 12.666667 | P20: =ROUND(MAX(0,MIN(J28)-MAX(M19,M14,M10)-H20),6) -> 0 | Q20: =IF(ABS(N20)<0.000001,"да","")
A21: 4.3 | B21: Очередь и календарь жеребцов | C21: исключён | D21: ='Данные'!J21 -> 39 | E21: ='Данные'!K21 -> 6.3333333 | F21: — | G21: — | H21: — | I21: — | J21: — | K21: — | L21: — | M21: — | N21: — | O21: — | P21: — | Q21: —
A22: 5.1 | B22: Кабинет клиента и заявки | C22: обычная | D22: ='Данные'!J22 -> 34.666667 | E22: ='Данные'!K22 -> 5.3333333 | F22: BA, UX2 | G22: 3.8 | H22: =D22/G22 -> 9.122807 | I22: =E22/G22 -> 1.4035088 | J22: =MAX(K10,K11,K14) -> 17.963801 | K22: =J22+H22 -> 27.086608 | L22: =ROUND(M22-H22,9) -> 30.465994 | M22: =MIN(L28) -> 39.588801 | N22: =ROUND(L22-J22,6) -> 12.502193 | O22: =ROUND(MIN(J28)-K22,6) -> 12.502193 | P22: =ROUND(MAX(0,MIN(J28)-MAX(M10,M11,M14)-H22),6) -> 12.502193 | Q22: =IF(ABS(N22)<0.000001,"да","")
A23: 5.2 | B23: Заказ семени с доставкой | C23: исключён | D23: ='Данные'!J23 -> 16.666667 | E23: ='Данные'!K23 -> 2.6666667 | F23: — | G23: — | H23: — | I23: — | J23: — | K23: — | L23: — | M23: — | N23: — | O23: — | P23: — | Q23: —
A24: 5.3 | B24: Счета и платежи | C24: исключён | D24: ='Данные'!J24 -> 31 | E24: ='Данные'!K24 -> 5 | F24: — | G24: — | H24: — | I24: — | J24: — | K24: — | L24: — | M24: — | N24: — | O24: — | P24: — | Q24: —
A25: 5.4 | B25: Отчёты и напоминания (Could) | C25: исключён | D25: ='Данные'!J25 -> 20.666667 | E25: ='Данные'!K25 -> 3.3333333 | F25: — | G25: — | H25: — | I25: — | J25: — | K25: — | L25: — | M25: — | N25: — | O25: — | P25: — | Q25: —
A26: 6.1 | B26: Интеграция внешних сервисов (заглушки) | C26: обычная | D26: ='Данные'!J26 -> 28.833333 | E26: ='Данные'!K26 -> 4.8333333 | F26: PM, TW | G26: 2.8 | H26: =D26/G26 -> 10.297619 | I26: =E26/G26 -> 1.7261905 | J26: =MAX(K10,K12) -> 9.1176471 | K26: =J26+H26 -> 19.415266 | L26: =ROUND(M26-H26,9) -> 29.291182 | M26: =MIN(L28) -> 39.588801 | N26: =ROUND(L26-J26,6) -> 20.173535 | O26: =ROUND(MIN(J28)-K26,6) -> 20.173535 | P26: =ROUND(MAX(0,MIN(J28)-MAX(M10,M12)-H26),6) -> 20.173535 | Q26: =IF(ABS(N26)<0.000001,"да","")
A27: 6.2 | B27: Тестирование и исправление дефектов | C27: гамак | D27: ='Данные'!J27 -> 56.666667 | E27: ='Данные'!K27 -> 8.3333333 | F27: QA, TW | G27: — | H27: =K27-J27 -> 27.565171 | I27: — | J27: =J14 -> 12.02363 | K27: =J28 -> 39.588801 | L27: — | M27: — | N27: — | O27: — | P27: — | Q27: —
A28: 6.3 | B28: Демонстрации и приёмка | C28: обычная | D28: ='Данные'!J28 -> 24.666667 | E28: ='Данные'!K28 -> 3.3333333 | F28: PM, BA, UX1, UX2, QA, TW, BE | G28: 12.2 | H28: =D28/G28 -> 2.0218579 | I28: =E28/G28 -> 0.27322404 | J28: =MAX(K20,K22,K26,K29) -> 39.588801 | K28: =J28+H28 -> 41.610659 | L28: =ROUND(M28-H28,9) -> 39.588801 | M28: =MIN(L8) -> 41.610659 | N28: =ROUND(L28-J28,6) -> 0 | O28: =ROUND(MIN(J8)-K28,6) -> 0 | P28: =ROUND(MAX(0,MIN(J8)-MAX(M20,M22,M26,M29)-H28),6) -> 0 | Q28: =IF(ABS(N28)<0.000001,"да","") -> да
A29: 6.4 | B29: Документация и приёмочные материалы | C29: обычная | D29: ='Данные'!J29 -> 18.666667 | E29: ='Данные'!K29 -> 2.6666667 | F29: TW, PM | G29: 2.8 | H29: =D29/G29 -> 6.6666667 | I29: =E29/G29 -> 0.95238095 | J29: =MAX(K17,K18) -> 32.922134 | K29: =J29+H29 -> 39.588801 | L29: =ROUND(M29-H29,9) -> 32.922134 | M29: =MIN(L28) -> 39.588801 | N29: =ROUND(L29-J29,6) -> 0 | O29: =ROUND(MIN(J28)-K29,6) -> 0 | P29: =ROUND(MAX(0,MIN(J28)-MAX(M17,M18)-H29),6) -> 0 | Q29: =IF(ABS(N29)<0.000001,"да","") -> да
B31: Tкр (окончание финальной приёмки 6.3), раб. дн | D31: =K28 -> 41.610659
B32: Окончание проекта (1.4), раб. дн | D32: =K8 -> 44.777325
B33: Tдир (25.12.2026), раб. дн | D33: 49
B34: Критический путь: 2.2 → 2.5 → 3.1 → 3.2 → 3.5 → 6.4 → 6.3 → 1.4
B36: D = E ост. / мощность; σ (дн) = σ ост. (ч) / мощность. ES = max EF предшественниц; EF = ES + D; LF = min LS последователей; LS = LF − D.
B37: Rполн = LS − ES; Rсвоб = min ES последователей − EF; Rнез = max(0; min ES последователей − max LF предшественниц − D).
B38: Гамак — растянутая работа: длительность берётся из сети, резервы не считаются.

Sheet События
A1: Ранние и поздние сроки событий (вариант Б)
A2: Событие — окончание работы: TE = EF, TL = LF. Рабочие дни от 19.10.2026.
A4: Событие | B4: Содержание | C4: Завершается работа | D4: Могут начаться | E4: TE | F4: TL | G4: Резерв
A5: 0 | B5: Начало оставшихся работ (статус-дата) | C5: — | D5: 1.2, 2.2, 2.3, 2.4, 4.1 | E5: 0 | F5: 0 | G5: =F5-E5 -> 0
A6: 1 | B6: Готово: Подготовка среды и инструментов | C6: 2.4 | D6: 2.5, 3.1, 6.1 | E6: ='PERT (вариант Б)'!K12 -> 3.7878788 | F6: ='PERT (вариант Б)'!M12 -> 9.1176471 | G6: =ROUND(F6-E6,6) -> 5.329768
A7: 2 | B7: Готово: Планирование проекта | C7: 1.2 | D7: 3.1 | E7: ='PERT (вариант Б)'!K6 -> 4.6666667 | F7: ='PERT (вариант Б)'!M6 -> 12.02363 | G7: =ROUND(F7-E7,6) -> 7.356963
A8: 3 | B8: Готово: Формализация правил совместимости | C8: 4.1 | D8: 4.2 | E8: ='PERT (вариант Б)'!K19 -> 5.2380952 | F8: ='PERT (вариант Б)'!M19 -> 30.630468 | G8: =ROUND(F8-E8,6) -> 25.392372
A9: 4 | B9: Готово: Проектирование пользовательского интерфейса | C9: 2.3 | D9: 3.1, 3.3, 5.1 | E9: ='PERT (вариант Б)'!K11 -> 8.1439394 | F9: ='PERT (вариант Б)'!M11 -> 12.02363 | G9: =ROUND(F9-E9,6) -> 3.879691
A10: 5 | B10: Готово: Проектирование архитектуры и базы данных | C10: 2.2 | D10: 2.5, 3.1, 4.2, 5.1, 6.1 | E10: ='PERT (вариант Б)'!K10 -> 9.1176471 | F10: ='PERT (вариант Б)'!M10 -> 9.1176471 | G10: =ROUND(F10-E10,6) -> 0
A11: 6 | B11: Готово: Подготовка демонстрационных данных | C11: 2.5 | D11: 3.1, 3.4, 3.5 | E11: ='PERT (вариант Б)'!K13 -> 12.02363 | F11: ='PERT (вариант Б)'!M13 -> 12.02363 | G11: =ROUND(F11-E11,6) -> 0
A12: 7 | B12: Готово: Реестр лошадей и карточка лошади | C12: 3.1 | D12: 3.2, 3.3, 3.4, 4.2, 5.1 | E12: ='PERT (вариант Б)'!K14 -> 17.963801 | F12: ='PERT (вариант Б)'!M14 -> 17.963801 | G12: =ROUND(F12-E12,6) -> 0
A13: 8 | B13: Готово: Интеграция внешних сервисов (заглушки) | C13: 6.1 | D13: 6.3 | E13: ='PERT (вариант Б)'!K26 -> 19.415266 | F13: ='PERT (вариант Б)'!M26 -> 39.588801 | G13: =ROUND(F13-E13,6) -> 20.173535
A14: 9 | B14: Готово: Ввод записей о состоянии и происшествиях | C14: 3.3 | D14: 3.4, 3.5 | E14: ='PERT (вариант Б)'!K16 -> 23.402397 | F14: ='PERT (вариант Б)'!M16 -> 25.713801 | G14: =ROUND(F14-E14,6) -> 2.311404
A15: 10 | B15: Готово: Размещение и перемещения | C15: 3.2 | D15: 3.5 | E15: ='PERT (вариант Б)'!K15 -> 25.713801 | F15: ='PERT (вариант Б)'!M15 -> 25.713801 | G15: =ROUND(F15-E15,6) -> 0
A16: 11 | B16: Готово: Проверка совместимости пар | C16: 4.2 | D16: 6.3 | E16: ='PERT (вариант Б)'!K20 -> 26.922134 | F16: ='PERT (вариант Б)'!M20 -> 39.588801 | G16: =ROUND(F16-E16,6) -> 12.666667
A17: 12 | B17: Готово: Кабинет клиента и заявки | C17: 5.1 | D17: 6.3 | E17: ='PERT (вариант Б)'!K22 -> 27.086608 | F17: ='PERT (вариант Б)'!M22 -> 39.588801 | G17: =ROUND(F17-E17,6) -> 12.502193
A18: 13 | B18: Готово: Справка «История жеребца» | C18: 3.4 | D18: 6.4 | E18: ='PERT (вариант Б)'!K17 -> 30.507661 | F18: ='PERT (вариант Б)'!M17 -> 32.922134 | G18: =ROUND(F18-E18,6) -> 2.414474
A19: 14 | B19: Готово: Справка «Перемещения и контакты» | C19: 3.5 | D19: 6.4 | E19: ='PERT (вариант Б)'!K18 -> 32.922134 | F19: ='PERT (вариант Б)'!M18 -> 32.922134 | G19: =ROUND(F19-E19,6) -> 0
A20: 15 | B20: Готово: Документация и приёмочные материалы | C20: 6.4 | D20: 6.3 | E20: ='PERT (вариант Б)'!K29 -> 39.588801 | F20: ='PERT (вариант Б)'!M29 -> 39.588801 | G20: =ROUND(F20-E20,6) -> 0
A21: 16 | B21: Финальная приёмка пройдена | C21: 6.3 | D21: 1.4 | E21: ='PERT (вариант Б)'!K28 -> 41.610659 | F21: ='PERT (вариант Б)'!M28 -> 41.610659 | G21: =ROUND(F21-E21,6) -> 0
A22: 17 | B22: Проект закрыт | C22: 1.4 | D22: — | E22: ='PERT (вариант Б)'!K8 -> 44.777325 | F22: ='PERT (вариант Б)'!M8 -> 44.777325 | G22: =ROUND(F22-E22,6) -> 0

Sheet Вероятность
A1: Вероятность выполнения в срок и сверка с уставом
A3: Вероятность срока (по сети)
A4: Показатель | B4: Вариант А | C4: Вариант Б | D4: Формула
A5: Часов в неделю | B5: 54 | C5: 68
A6: Пакетов в расчёте | B6: 24 | C6: 20
A7: Tкр, раб. дн | B7: ='PERT (вариант А)'!D31 -> 54.801556 | C7: ='PERT (вариант Б)'!D31 -> 41.610659 | D7: EF работы 6.3
A8: Критический путь | B8: 2.2 → 2.5 → 3.1 → 3.2 → 3.5 → 6.4 → 6.3 | C8: 2.2 → 2.5 → 3.1 → 3.2 → 3.5 → 6.4 → 6.3
A9: σкр, раб. дн | B9: =SQRT('PERT (вариант А)'!I10^2+'PERT (вариант А)'!I13^2+'PERT (вариант А)'!I14^2+'PERT (вариант А)'!I15^2+'PERT (вариант А)'!I18^2+'PERT (вариант А)'!I29^2+'PERT (вариант А)'!I28^2) -> 3.5267547 | C9: =SQRT('PERT (вариант Б)'!I10^2+'PERT (вариант Б)'!I13^2+'PERT (вариант Б)'!I14^2+'PERT (вариант Б)'!I15^2+'PERT (вариант Б)'!I18^2+'PERT (вариант Б)'!I29^2+'PERT (вариант Б)'!I28^2) -> 2.6898431 | D9: √Σσ² по критическому пути
A10: Tдир, раб. дн | B10: 49 | C10: 49 | D10: 19.10–25.12.2026
A11: Tдир − Tкр, раб. дн | B11: =B10-B7 -> -5.8015556 | C11: =C10-C7 -> 7.3893412
A12: z | B12: =(B10-B7)/B9 -> -1.6450125 | C12: =(C10-C7)/C9 -> 2.7471272 | D12: (Tдир − Tкр) / σкр
A13: P(T ≤ Tдир) | B13: =NORMSDIST(B12) -> 0.049983616 | C13: =NORMSDIST(C12) -> 0.99699401 | D13: Ф(z)
A15: Трудоёмкость и фонд времени
A16: Показатель | B16: Вариант А | C16: Вариант Б | D16: Формула
A17: ΣE всех пакетов, ч | B17: ='Данные'!G30 -> 735.83333 | C17: ='Данные'!G30 -> 735.83333
A18: Фонд времени по уставу, ч | B18: 810 | C18: 810 | D18: 54 ч/нед × 15 нед
A19: Запас фонда, ч | B19: =B18-B17 -> 74.166667 | C19: =C18-C17 -> 74.166667
A20: Выполнено на 17.10, ч | B20: ='Данные'!G30-'Данные'!J30 -> 81.867722 | C20: ='Данные'!G30-'Данные'!J30 -> 81.867722
A21: Остаток работ, ч | B21: ='Данные'!J30 -> 653.96561 | C21: ='Данные'!Q30 -> 546.63228
A22: Рабочих дней 19.10–31.12 | B22: 53 | C22: 53
A23: Фонд оставшегося времени, ч | B23: =B22*B5/5 -> 572.4 | C23: =C22*C5/5 -> 720.8 | D23: дни × ч/нед / 5
A24: Запас (+) / дефицит (−), ч | B24: =B23-B21 -> -81.565612 | C24: =C23-C21 -> 174.16772
A25: Загрузка фонда | B25: =B21/B23 -> 1.1424976 | C25: =C21/C23 -> 0.75836887
A26: Всего часов по плану | B26: =B20+B21 -> 735.83333 | C26: =C20+C21 -> 628.5
A28: Стоимость, USD
A29: Показатель | B29: Вариант А | C29: Вариант Б | D29: Формула
A30: Работы по ставкам исполнителей | B30: 41176 | C30: 34706 | D30: часы × ставка
A31: Резерв на риски 10% | B31: =B30*0.1 -> 4117.6 | C31: =C30*0.1 -> 3470.6
A32: Итого с резервом | B32: =B30+B31 -> 45293.6 | C32: =C30+C31 -> 38176.6
A33: Потолок бюджета | B33: 50000 | C33: 50000
A34: Запас до потолка | B34: =B33-B32 -> 4706.4 | C34: =C33-C32 -> 11823.4
A35: По средней ставке 55 USD/ч | B35: =B26*55 -> 40470.833 | C35: =C26*55 -> 34567.5 | D35: как в сводной таблице
A37: После выравнивания ресурсов (расписание)
A38: Показатель | B38: Вариант А | C38: Вариант Б | D38: Формула
A39: Окончание 6.3 | B39: 12.02.2027 | C39: 18.12.2026
A40: Запас до 25.12, раб. дн | B40: -28.504102 | C40: 5.0976745
A41: P(успеть) | B41: 8.5287277e-11 | C41: 0.96021089
A43: Вывод
A44: Вариант А (все пакеты, 54 ч/нед) в срок не укладывается: Tкр = 54,8 раб. дн при Tдир = 49, P = 5,0%. Остаток работ 654 ч больше фонда оставшегося времени 572 ч.
A45: Вариант Б (Must и 5.1, каждому +2 ч/нед): Tкр = 41,6 раб. дн, P = 99,7%. После выравнивания ресурсов приёмка заканчивается 18.12.2026, запас 5,1 раб. дн, P = 96%.
...

Sheet Сценарии
A1: Сценарии: недельная нагрузка и состав пакетов
A3: Вариант | B3: Ч/нед | C3: Состав | D3: Остаток работ, ч | E3: Фонд 19.10–31.12, ч | F3: Загрузка фонда | G3: Tкр, дн | H3: P по сети | I3: Окончание 6.3 | J3: Запас до 25.12, дн | K3: P по расписанию | L3: Итог
A4: А | B4: 54 | C4: Полный объём (25 пакетов) | D4: 653.96561 | E4: 572.4 | F4: 1.1424976 | G4: 54.801556 | H4: 0.049983616 | I4: 12.02.2027 | J4: -28.504102 | K4: 8.5287277e-11 | L4: не укладывается
B5: 54 | C5: Без 5.4 (Could) | D5: 633.29895 | E5: 572.4 | F5: 1.1063923 | G5: 54.801556 | H5: 0.049983616 | I5: 12.02.2027 | J5: -28.504102 | K5: 8.5287277e-11 | L5: не укладывается
B6: 54 | C6: Must + 5.1 | D6: 546.63228 | E6: 572.4 | F6: 0.95498302 | G6: 54.801556 | H6: 0.049983616 | I6: 13.01.2027 | J6: -6.6291019 | K6: 0.035945865 | L6: не укладывается
B7: 54 | C7: Только Must | D7: 511.96561 | E7: 572.4 | F7: 0.89441931 | G7: 54.801556 | H7: 0.049983616 | I7: 13.01.2027 | J7: -6.6291019 | K7: 0.035945865 | L7: не укладывается
B8: 61 | C8: Must + 5.1 | D8: 546.63228 | E8: 646.6 | F8: 0.8453948 | G8: 47.232085 | H8: 0.71918931 | I8: 25.12.2026 | J8: -0.069846215 | K8: 0.49142532 | L8: не укладывается
B9: 68 | C9: Полный объём (25 пакетов) | D9: 653.96561 | E9: 720.8 | F9: 0.90727749 | G9: 42.924255 | H9: 0.9833708 | I9: 20.01.2027 | J9: -12.402325 | K9: 0.00022874338 | L9: не укладывается
B10: 68 | C10: Must + 4.3 + 5.1 | D10: 585.63228 | E10: 720.8 | F10: 0.81247541 | G10: 41.610659 | H10: 0.99699401 | I10: 11.01.2027 | J10: -4.6523255 | K10: 0.07998625 | L10: не укладывается
A11: Б | B11: 68 | C11: Must + 5.1 — базовый план | D11: 546.63228 | E11: 720.8 | F11: 0.75836887 | G11: 41.610659 | H11: 0.99699401 | I11: 18.12.2026 | J11: 5.0976745 | K11: 0.96021089 | L11: укладывается
B12: 68 | C12: Must + 4.3 вместо 5.1 | D12: 550.96561 | E12: 720.8 | F12: 0.7643807 | G12: 41.610659 | H12: 0.99699401 | I12: 18.12.2026 | J12: 5.0976745 | K12: 0.96021089 | L12: укладывается
B13: 68 | C13: Только Must | D13: 511.96561 | E13: 720.8 | F13: 0.71027416 | G13: 41.610659 | H13: 0.99699401 | I13: 18.12.2026 | J13: 5.0976745 | K13: 0.96021089 | L13: укладывается
B14: 75 | C14: Must + 4.3 + 5.1 | D14: 585.63228 | E14: 795 | F14: 0.73664438 | G14: 37.236688 | H14: 0.99999946 | I14: 25.12.2026 | J14: 0.41230223 | K14: 0.55466571 | L14: на грани
B15: 82 | C15: Must + 4.3 + 5.1 | D15: 585.63228 | E15: 869.2 | F15: 0.6737601 | G15: 33.721743 | H15: 1 | I15: 18.12.2026 | J15: 4.6002595 | K15: 0.95330578 | L15: укладывается
B16: 82 | C16: Полный объём (25 пакетов) | D16: 653.96561 | E16: 869.2 | F16: 0.75237645 | G16: 35.420272 | H16: 1 | I16: 29.12.2026 | J16: -1.8580738 | K16: 0.26320603 | L16: не укладывается
A18: Запас от 3 раб. дн — укладывается, от 0 до 3 — на грани.
A19: При 54 ч/нед не помещаются даже Must-пакеты. При +2 ч/нед каждому помещаются Must и один пакет Should (5.1 или 4.3).

Sheet Изменения
A1: Изменения к уставу (запрос на изменение № 1)
A2: Требуют согласования по п. 4.2 устава.
A4: № | B4: Что меняется | C4: По уставу | D4: Предлагается | E4: Согласует | F4: Последствия
A5: 1 | B5: Часы в неделю | C5: 54 (10 / 8 / 10 / 8 / 6 / 6 / 6) | D5: 68: каждому +2 ч с 19.10 по 31.12 | E5: команда, куратор, заказчик | F5: Всего по плану 628 ч (фонд 810 ч). Стоимость 34 706 USD, с резервом 38 177 USD.
A6: 2 | B6: Пакет 5.4 (Could) | C6: по возможности | D6: исключить | E6: урезается первым по п. 3.3 | F6: Снимается критерий приёмки 16.
A7: 3 | B7: Пакеты Should | C7: 4.3, 5.1, 5.2, 5.3 | D7: оставить 5.1; исключить 4.3, 5.2, 5.3 | E7: заказчик | F7: Ц5 не выполняется, Ц4 частично. Сквозной сценарий: заявка, проверка совместимости, реестр. Критерии 9 и 10 снимаются, 8 и 11 уточняются.
A8: 4 | B8: Какой пакет Should оставить | C8: приоритеты А-14: очередь, заявки, счета | D8: 5.1 (вторая роль пользователя — клиент). Замена с тем же сроком: 4.3 | E8: заказчик | F8: С 5.1 нет очереди и календаря, с 4.3 нет роли клиента.
A9: 5 | B9: Содержание вех | C9: В1: реестр, размещение; В2: справки, ввод записей; В3: совместимость, заявки, очередь; В4: счета, приёмка | D9: В1: 2.5, 3.1, 4.1; В2: 3.2, 3.3, 6.1; В3: 3.4, 3.5; В4: 4.2, 5.1, 6.4, приёмка | E9: заказчик, куратор | F9: Справки показываются на В3 вместо В2, размещение на В2 вместо В1. Пакеты 4.2 и 5.1 показываются на финальной паре.
A10: 6 | B10: Если +2 ч/нед не согласованы | C10: — | D10: при 54 ч/нед Must-пакеты заканчиваются 13.01.2027 | E10: заказчик, куратор | F10: Придётся урезать Must-пакеты или понизить уровень реализации.

Sheet Допущения
A1: Допущения расчёта
A3: 1 | B3: Статус-дата 17.10.2026. Рассчитываются оставшиеся работы, отсчёт с 19.10.2026. Рабочие дни: пн–пт, кроме 04.11.2026.
A4: 2 | B4: Готовность на статус-дату: 1.1 — 100%, 1.2 — 60%, 2.1 — 70%, 1.3 — 38% (по времени), остальные пакеты не начаты.
A5: 3 | B5: O, M, P взяты из сводной таблицы оценок. E = (O + 4M + P) / 6, σ = (P − O) / 6. Для начатых пакетов остаток пропорционален готовности.
A6: 4 | B6: D = E ост. / мощность. Мощность — сумма часов в день исполнителей пакета (ч/нед : 5) без часов, занятых гамаками.
A7: 5 | B7: Гамаки (растянутые работы): 1.3, остаток 2.1, 6.2. Длительность берётся из сети. Под них отведено: руководитель проекта 4 ч/нед, аналитик 1 ч/нед, техред 2 ч/нед (в варианте А 3 ч/нед); тестировщик с начала 3.1 занят только тестированием.
A8: 6 | B8: 6.3 в сети — подготовка и проведение финальной приёмки. Tдир = 49 раб. дн (25.12.2026, последний рабочий день перед парой 26.12). Закрытие 1.4 — 28–31.12.2026.
A9: 7 | B9: Связи «окончание–начало» взяты из сводной таблицы оценок, отличия указаны на листе «Данные».
A10: 8 | B10: Вероятность срока: z = (Tдир − Tкр) / σкр, σкр = √Σσ² по критическому пути, P = Ф(z).
A11: 9 | B11: Расписание: один человек одновременно занят в одном пакете; при конфликте раньше идёт работа с меньшим поздним началом (файл «Расписание»).
A12: 10 | B12: Стоимость — часы исполнителя × его ставка (устав, п. 5.5).
A13: 11 | B13: В команде 7 человек (устав, п. 3.3).
A14: 12 | B14: Сеть рассчитана формулами на листах PERT. Выравнивание ресурсов и рисунки выполнены программой на Python.

Sheet Сетевой график
