Workbook

Sheet Бэклог продукта
A1: Бэклог продукта Stud Book
A2: Порядок строк — порядок выполнения (ранг 1 — первым). Приоритет MoSCoW по уставу. Итерации и вехи — по базовому плану (расписание v1.0, вариант Б). Оценка в часах — ориентир: остаток трудоёмкости пакета, делённый поровну на позиции с этим пакетом. Столбец «Оценка, SP» заполняется на покере планирования.
A4: Ранг | B4: ID | C4: Тип | D4: Роль или представление | E4: Название | F4: Описание | G4: Приоритет MoSCoW | H4: Основной пакет ИСР | I4: Предшественники пакета | J4: Итерация | K4: Веха и дата | L4: Критерий приёмки (п. 2.4) | M4: Оценка, ч (ориентир) | N4: Оценка, SP | O4: Статус | P4: Требование или допущение | Q4: Примечание
A5: 1 | B5: W-1.1 | C5: Работа по ИСР | D5: Команда | E5: Инициация проекта | F5: Устав, реестр заинтересованных сторон, отчёт о применимости методологий. | G5: Must | H5: 1.1 | I5: =IFERROR(INDEX('Пакеты ИСР'!$E$5:$E$29,MATCH($H5,'Пакеты ИСР'!$A$5:$A$29,0)),"") -> — | J5: Нулевой спринт | K5: =IFERROR(INDEX('План итераций'!$C$5:$C$11,MATCH($J5,'План итераций'!$A$5:$A$11,0)),"") -> Фаза 4, 31.10.2026 | M5: =IFERROR(INDEX('Пакеты ИСР'!$D$5:$D$29,MATCH($H5,'Пакеты ИСР'!$A$5:$A$29,0))/COUNTIF($H$5:$H$55,$H5),0) -> 0 | O5: Выполнено | Q5: Выполнено до фазы 3
A6: 2 | B6: W-2.2 | C6: Работа по ИСР | D6: Команда | E6: Проектирование архитектуры и базы данных | F6: Структура клиент, сервер, заглушки; модель данных; две роли. | G6: Must | H6: 2.2 | I6: =IFERROR(INDEX('Пакеты ИСР'!$E$5:$E$29,MATCH($H6,'Пакеты ИСР'!$A$5:$A$29,0)),"") -> 2.1 | J6: Нулевой спринт | K6: =IFERROR(INDEX('План итераций'!$C$5:$C$11,MATCH($J6,'План итераций'!$A$5:$A$11,0)),"") -> Фаза 4, 31.10.2026 | M6: =IFERROR(INDEX('Пакеты ИСР'!$D$5:$D$29,MATCH($H6,'Пакеты ИСР'!$A$5:$A$29,0))/COUNTIF($H$5:$H$55,$H6),0) -> 31 | O6: К выполнению
A7: 3 | B7: W-2.4 | C7: Работа по ИСР | D7: Команда | E7: Подготовка среды и инструментов | F7: Репозиторий GitHub, Issues и Projects, Figma, каркас приложения, демонстрационный стенд. | G7: Must | H7: 2.4 | I7: =IFERROR(INDEX('Пакеты ИСР'!$E$5:$E$29,MATCH($H7,'Пакеты ИСР'!$A$5:$A$29,0)),"") -> 1.2 | J7: Нулевой спринт | K7: =IFERROR(INDEX('План итераций'!$C$5:$C$11,MATCH($J7,'План итераций'!$A$5:$A$11,0)),"") -> Фаза 4, 31.10.2026 | M7: =IFERROR(INDEX('Пакеты ИСР'!$D$5:$D$29,MATCH($H7,'Пакеты ИСР'!$A$5:$A$29,0))/COUNTIF($H$5:$H$55,$H7),0) -> 8.335 | O7: К выполнению
A8: 4 | B8: SH-01 | C8: Обеспечивающая история | D8: Все роли | E8: Вход и выбор роли | F8: Как пользователь системы, я хочу войти и выбрать роль (клиент или сотрудник ранчо), чтобы видеть только нужные мне экраны. | G8: Must | H8: 2.4 | I8: =IFERROR(INDEX('Пакеты ИСР'!$E$5:$E$29,MATCH($H8,'Пакеты ИСР'!$A$5:$A$29,0)),"") -> 1.2 | J8: Нулевой спринт | K8: =IFERROR(INDEX('План итераций'!$C$5:$C$11,MATCH($J8,'План итераций'!$A$5:$A$11,0)),"") -> Фаза 4, 31.10.2026 | L8: 11 | M8: =IFERROR(INDEX('Пакеты ИСР'!$D$5:$D$29,MATCH($H8,'Пакеты ИСР'!$A$5:$A$29,0))/COUNTIF($H$5:$H$55,$H8),0) -> 8.335 | O8: К выполнению | P8: А-11 | Q8: Пакет 2.4 делится с работой W-2.4: вес по умолчанию равный, уточнить на покере
A9: 5 | B9: SH-02 | C9: Обеспечивающая история | D9: Все роли | E9: Стиль «племенной книги» | F9: Как заказчик, я хочу, чтобы интерфейс был оформлен в духе «племенной книги» и не напоминал приложение для знакомств, чтобы продукт подходил ранчо. | G9: Must | H9: 2.3 | I9: =IFERROR(INDEX('Пакеты ИСР'!$E$5:$E$29,MATCH($H9,'Пакеты ИСР'!$A$5:$A$29,0)),"") -> 2.1, 2.2 | J9: Нулевой спринт | K9: =IFERROR(INDEX('План итераций'!$C$5:$C$11,MATCH($J9,'План итераций'!$A$5:$A$11,0)),"") -> Фаза 4, 31.10.2026 | L9: 12 | M9: =IFERROR(INDEX('Пакеты ИСР'!$D$5:$D$29,MATCH($H9,'Пакеты ИСР'!$A$5:$A$29,0))/COUNTIF($H$5:$H$55,$H9),0) -> 17.915 | O9: К выполнению | P9: Т-13
A10: 6 | B10: SH-03 | C10: Обеспечивающая история | D10: Все роли | E10: Английский язык и адаптивная раскладка | F10: Как клиент или сотрудник ранчо, я хочу пользоваться системой на английском языке с телефона, планшета и компьютера, чтобы работать в ней откуда угодно. | G10: Should | H10: 2.3 | I10: =IFERROR(INDEX('Пакеты ИСР'!$E$5:$E$29,MATCH($H10,'Пакеты ИСР'!$A$5:$A$29,0)),"") -> 2.1, 2.2 | J10: Нулевой спринт | K10: =IFERROR(INDEX('План итераций'!$C$5:$C$11,MATCH($J10,'План итераций'!$A$5:$A$11,0)),"") -> Фаза 4, 31.10.2026 | M10: =IFERROR(INDEX('Пакеты ИСР'!$D$5:$D$29,MATCH($H10,'Пакеты ИСР'!$A$5:$A$29,0))/COUNTIF($H$5:$H$55,$H10),0) -> 17.915 | O10: К выполнению | P10: Т-14; А-12 | Q10: Допущение А-12 ещё не подтверждено заказчиком
A11: 7 | B11: W-1.2 | C11: Работа по ИСР | D11: Команда | E11: Планирование проекта (остаток) | F11: Story map, бэклог продукта, план итерации 1; далее планирование перед каждой итерацией. | G11: Must | H11: 1.2 | I11: =IFERROR(INDEX('Пакеты ИСР'!$E$5:$E$29,MATCH($H11,'Пакеты ИСР'!$A$5:$A$29,0)),"") -> 1.1 | J11: Нулевой спринт | K11: =IFERROR(INDEX('План итераций'!$C$5:$C$11,MATCH($J11,'План итераций'!$A$5:$A$11,0)),"") -> Фаза 4, 31.10.2026 | M11: =IFERROR(INDEX('Пакеты ИСР'!$D$5:$D$29,MATCH($H11,'Пакеты ИСР'!$A$5:$A$29,0))/COUNTIF($H$5:$H$55,$H11),0) -> 13.07 | O11: К выполнению | Q11: Планирование следующих итераций повторяется перед каждой
A12: 8 | B12: OW-15 | C12: История | D12: Сотрудник ранчо, Владелец (Дасти) | E12: Таблица правил совместимости | F12: Как сотрудник ранчо, я хочу, чтобы правила допустимости пар хранились единой таблицей, согласованной с ветеринаром, чтобы все проверки шли по одним правилам. | G12: Must | H12: 4.1 | I12: =IFERROR(INDEX('Пакеты ИСР'!$E$5:$E$29,MATCH($H12,'Пакеты ИСР'!$A$5:$A$29,0)),"") -> 2.1 | J12: Итерация 1 | K12: =IFERROR(INDEX('План итераций'!$C$5:$C$11,MATCH($J12,'План итераций'!$A$5:$A$11,0)),"") -> В1, 14.11.2026 | L12: 7 | M12: =IFERROR(INDEX('Пакеты ИСР'!$D$5:$D$29,MATCH($H12,'Пакеты ИСР'!$A$5:$A$29,0))/COUNTIF($H$5:$H$55,$H12),0) -> 14.67 | N12: 3 | O12: К выполнению | P12: Т-07; А-9 | Q12: Таблицу правил даёт заказчик с ветеринаром до 14.11.2026 (А-9); начать первой. Риск Р2
A13: 9 | B13: OW-01 | C13: История | D13: Сотрудник ранчо, Владелец (Дасти) | E13: Реестр лошадей трёх категорий | F13: Как сотрудник ранчо, я хочу видеть реестр лошадей трёх категорий (свои жеребцы, жеребцы на управлении, кобылы клиентов), чтобы знать, кто есть на ранчо. | G13: Must | H13: 3.1 | I13: =IFERROR(INDEX('Пакеты ИСР'!$E$5:$E$29,MATCH($H13,'Пакеты ИСР'!$A$5:$A$29,0)),"") -> 2.2, 2.3, 2.4, 2.5 | J13: Итерация 1 | K13: =IFERROR(INDEX('План итераций'!$C$5:$C$11,MATCH($J13,'План итераций'!$A$5:$A$11,0)),"") -> В1, 14.11.2026 | L13: 1 | M13: =IFERROR(INDEX('Пакеты ИСР'!$D$5:$D$29,MATCH($H13,'Пакеты ИСР'!$A$5:$A$29,0))/COUNTIF($H$5:$H$55,$H13),0) -> 15.443333 | N13: 5 | O13: К выполнению | P13: Т-01
A14: 10 | B14: OW-02 | C14: История | D14: Сотрудник ранчо, Владелец (Дасти) | E14: Карточка лошади с родословной | F14: Как сотрудник ранчо, я хочу открыть карточку лошади с родословной минимум на два поколения, чтобы проверять происхождение без бумажного журнала. | G14: Must | H14: 3.1 | I14: =IFERROR(INDEX('Пакеты ИСР'!$E$5:$E$29,MATCH($H14,'Пакеты ИСР'!$A$5:$A$29,0)),"") -> 2.2, 2.3, 2.4, 2.5 | J14: Итерация 1 | K14: =IFERROR(INDEX('План итераций'!$C$5:$C$11,MATCH($J14,'План итераций'!$A$5:$A$11,0)),"") -> В1, 14.11.2026 | L14: 1 | M14: =IFERROR(INDEX('Пакеты ИСР'!$D$5:$D$29,MATCH($H14,'Пакеты ИСР'!$A$5:$A$29,0))/COUNTIF($H$5:$H$55,$H14),0) -> 15.443333 | N14: 8 | O14: К выполнению | P14: Т-01
A15: 11 | B15: OW-03 | C15: История | D15: Сотрудник ранчо, Владелец (Дасти) | E15: Добавить лошадь в реестр | F15: Как сотрудник ранчо, я хочу добавить лошадь в реестр и указать её происхождение, чтобы реестр оставался актуальным. | G15: Must | H15: 3.1 | I15: =IFERROR(INDEX('Пакеты ИСР'!$E$5:$E$29,MATCH($H15,'Пакеты ИСР'!$A$5:$A$29,0)),"") -> 2.2, 2.3, 2.4, 2.5 | J15: Итерация 1 | K15: =IFERROR(INDEX('План итераций'!$C$5:$C$11,MATCH($J15,'План итераций'!$A$5:$A$11,0)),"") -> В1, 14.11.2026 | L15: 1 | M15: =IFERROR(INDEX('Пакеты ИСР'!$D$5:$D$29,MATCH($H15,'Пакеты ИСР'!$A$5:$A$29,0))/COUNTIF($H$5:$H$55,$H15),0) -> 15.443333 | N15: 5 | O15: К выполнению | P15: Т-01 | Q15: Вывод команды, подтвердить с заказчиком
A16: 12 | B16: SH-04 | C16: Обеспечивающая история | D16: Все роли | E16: Демонстрационные данные | F16: Как заказчик, я хочу видеть систему с демонстрационными данными (15 лошадей, 6 клиентов, 25 записей размещения и другие), чтобы оценить её работу на показе. | G16: Must | H16: 2.5 | I16: =IFERROR(INDEX('Пакеты ИСР'!$E$5:$E$29,MATCH($H16,'Пакеты ИСР'!$A$5:$A$29,0)),"") -> 2.2, 2.4 | J16: Итерация 1 | K16: =IFERROR(INDEX('План итераций'!$C$5:$C$11,MATCH($J16,'План итераций'!$A$5:$A$11,0)),"") -> В1, 14.11.2026 | L16: 14 | M16: =IFERROR(INDEX('Пакеты ИСР'!$D$5:$D$29,MATCH($H16,'Пакеты ИСР'!$A$5:$A$29,0))/COUNTIF($H$5:$H$55,$H16),0) -> 22.67 | N16: 5 | O16: К выполнению | P16: п. 2.1 устава
A17: 13 | B17: OW-04 | C17: История | D17: Сотрудник ранчо, Владелец (Дасти) | E17: Зафиксировать прибытие лошади | F17: Как сотрудник ранчо, я хочу зафиксировать прибытие лошади (дата, место, откуда прибыла), чтобы всегда знать, откуда она появилась. | G17: Must | H17: 3.2 | I17: =IFERROR(INDEX('Пакеты ИСР'!$E$5:$E$29,MATCH($H17,'Пакеты ИСР'!$A$5:$A$29,0)),"") -> 3.1 | J17: Итерация 2 | K17: =IFERROR(INDEX('План итераций'!$C$5:$C$11,MATCH($J17,'План итераций'!$A$5:$A$11,0)),"") -> В2, 28.11.2026 | L17: 2 | M17: =IFERROR(INDEX('Пакеты ИСР'!$D$5:$D$29,MATCH($H17,'Пакеты ИСР'!$A$5:$A$29,0))/COUNTIF($H$5:$H$55,$H17),0) -> 10.333333 | O17: К выполнению | P17: Т-02; А-8
A18: 14 | B18: OW-05 | C18: История | D18: Сотрудник ранчо, Владелец (Дасти) | E18: Зафиксировать отъезд лошади | F18: Как сотрудник ранчо, я хочу зафиксировать отъезд лошади, чтобы реестр показывал только тех, кто сейчас на ранчо. | G18: Must | H18: 3.2 | I18: =IFERROR(INDEX('Пакеты ИСР'!$E$5:$E$29,MATCH($H18,'Пакеты ИСР'!$A$5:$A$29,0)),"") -> 3.1 | J18: Итерация 2 | K18: =IFERROR(INDEX('План итераций'!$C$5:$C$11,MATCH($J18,'План итераций'!$A$5:$A$11,0)),"") -> В2, 28.11.2026 | L18: 2 | M18: =IFERROR(INDEX('Пакеты ИСР'!$D$5:$D$29,MATCH($H18,'Пакеты ИСР'!$A$5:$A$29,0))/COUNTIF($H$5:$H$55,$H18),0) -> 10.333333 | O18: К выполнению | P18: Т-02; А-8
A19: 15 | B19: OW-06 | C19: История | D19: Сотрудник ранчо, Владелец (Дасти) | E19: Где стоит лошадь и где была | F19: Как сотрудник ранчо, я хочу видеть, где сейчас стоит лошадь и где она была раньше, чтобы быстро отвечать на вопросы клиентов и регуляторов. | G19: Must | H19: 3.2 | I19: =IFERROR(INDEX('Пакеты ИСР'!$E$5:$E$29,MATCH($H19,'Пакеты ИСР'!$A$5:$A$29,0)),"") -> 3.1 | J19: Итерация 2 | K19: =IFERROR(INDEX('План итераций'!$C$5:$C$11,MATCH($J19,'План итераций'!$A$5:$A$11,0)),"") -> В2, 28.11.2026 | L19: 2 | M19: =IFERROR(INDEX('Пакеты ИСР'!$D$5:$D$29,MATCH($H19,'Пакеты ИСР'!$A$5:$A$29,0))/COUNTIF($H$5:$H$55,$H19),0) -> 10.333333 | O19: К выполнению | P19: Т-02; А-8
A20: 16 | B20: OW-07 | C20: История | D20: Сотрудник ранчо, Владелец (Дасти) | E20: Запись о готовности кобылы | F20: Как сотрудник ранчо, я хочу внести запись о готовности кобылы простой формой (не более семи полей и трёх шагов), чтобы сведения ветеринара не терялись. | G20: Must | H20: 3.3 | I20: =IFERROR(INDEX('Пакеты ИСР'!$E$5:$E$29,MATCH($H20,'Пакеты ИСР'!$A$5:$A$29,0)),"") -> 3.1, 2.3 | J20: Итерация 2 | K20: =IFERROR(INDEX('План итераций'!$C$5:$C$11,MATCH($J20,'План итераций'!$A$5:$A$11,0)),"") -> В2, 28.11.2026 | L20: 6 | M20: =IFERROR(INDEX('Пакеты ИСР'!$D$5:$D$29,MATCH($H20,'Пакеты ИСР'!$A$5:$A$29,0))/COUNTIF($H$5:$H$55,$H20),0) -> 6.89 | O20: К выполнению | P20: Т-06; Т-15; А-10
A21: 17 | B21: OW-08 | C21: История | D21: Сотрудник ранчо, Владелец (Дасти) | E21: Запись о травме или происшествии | F21: Как сотрудник ранчо, я хочу внести запись о травме или происшествии, чтобы она попадала в историю лошади. | G21: Must | H21: 3.3 | I21: =IFERROR(INDEX('Пакеты ИСР'!$E$5:$E$29,MATCH($H21,'Пакеты ИСР'!$A$5:$A$29,0)),"") -> 3.1, 2.3 | J21: Итерация 2 | K21: =IFERROR(INDEX('План итераций'!$C$5:$C$11,MATCH($J21,'План итераций'!$A$5:$A$11,0)),"") -> В2, 28.11.2026 | L21: 6 | M21: =IFERROR(INDEX('Пакеты ИСР'!$D$5:$D$29,MATCH($H21,'Пакеты ИСР'!$A$5:$A$29,0))/COUNTIF($H$5:$H$55,$H21),0) -> 6.89 | O21: К выполнению | P21: Т-06; А-10
A22: 18 | B22: OW-09 | C22: История | D22: Сотрудник ранчо, Владелец (Дасти) | E22: Запись о состоянии лошади | F22: Как сотрудник ранчо, я хочу внести запись о состоянии лошади, чтобы история была полной. | G22: Must | H22: 3.3 | I22: =IFERROR(INDEX('Пакеты ИСР'!$E$5:$E$29,MATCH($H22,'Пакеты ИСР'!$A$5:$A$29,0)),"") -> 3.1, 2.3 | J22: Итерация 2 | K22: =IFERROR(INDEX('План итераций'!$C$5:$C$11,MATCH($J22,'План итераций'!$A$5:$A$11,0)),"") -> В2, 28.11.2026 | L22: 6 | M22: =IFERROR(INDEX('Пакеты ИСР'!$D$5:$D$29,MATCH($H22,'Пакеты ИСР'!$A$5:$A$29,0))/COUNTIF($H$5:$H$55,$H22),0) -> 6.89 | O22: К выполнению | P22: Т-06; Т-15
A23: 19 | B23: SH-05 | C23: Обеспечивающая история | D23: Все роли | E23: Заглушки пяти внешних сервисов | F23: Как заказчик, я хочу, чтобы платежи, рассылки, обмен с породной ассоциацией, доставка семени и выгрузка справок были показаны заглушками, чтобы проверить сценарии без реальных интеграций. | G23: Must | H23: 6.1 | I23: =IFERROR(INDEX('Пакеты ИСР'!$E$5:$E$29,MATCH($H23,'Пакеты ИСР'!$A$5:$A$29,0)),"") -> 2.2, 2.4 | J23: Итерация 2 | K23: =IFERROR(INDEX('План итераций'!$C$5:$C$11,MATCH($J23,'План итераций'!$A$5:$A$11,0)),"") -> В2, 28.11.2026 | L23: 13 | M23: =IFERROR(INDEX('Пакеты ИСР'!$D$5:$D$29,MATCH($H23,'Пакеты ИСР'!$A$5:$A$29,0))/COUNTIF($H$5:$H$55,$H23),0) -> 9.61 | O23: К выполнению | P23: А-1…А-5
A24: 20 | B24: OW-12 | C24: История | D24: Сотрудник ранчо, Владелец (Дасти) | E24: Выгрузить справку файлом (заглушка) | F24: Как сотрудник ранчо, я хочу выгрузить справку в файл, чтобы передать её страховщику или регулятору. | G24: Should | H24: 6.1 | I24: =IFERROR(INDEX('Пакеты ИСР'!$E$5:$E$29,MATCH($H24,'Пакеты ИСР'!$A$5:$A$29,0)),"") -> 2.2, 2.4 | J24: Итерация 2 | K24: =IFERROR(INDEX('План итераций'!$C$5:$C$11,MATCH($J24,'План итераций'!$A$5:$A$11,0)),"") -> В2, 28.11.2026 | L24: 5 | M24: =IFERROR(INDEX('Пакеты ИСР'!$D$5:$D$29,MATCH($H24,'Пакеты ИСР'!$A$5:$A$29,0))/COUNTIF($H$5:$H$55,$H24),0) -> 9.61 | O24: К выполнению | P24: Т-05; А-5 | Q24: Образец файла статичный (А-5). Кнопка подключается к справкам в итерации 3 вместе с 3.4 и 3.5
A25: 21 | B25: CL-07 | C25: История | D25: Клиент | E25: Уведомление о статусе (заглушка) | F25: Как клиент, я хочу получать уведомление об изменении статуса заявки, чтобы не заходить в систему без необходимости. | G25: Could | H25: 6.1 | I25: =IFERROR(INDEX('Пакеты ИСР'!$E$5:$E$29,MATCH($H25,'Пакеты ИСР'!$A$5:$A$29,0)),"") -> 2.2, 2.4 | J25: Итерация 2 | K25: =IFERROR(INDEX('План итераций'!$C$5:$C$11,MATCH($J25,'План итераций'!$A$5:$A$11,0)),"") -> В2, 28.11.2026 | L25: 13 | M25: =IFERROR(INDEX('Пакеты ИСР'!$D$5:$D$29,MATCH($H25,'Пакеты ИСР'!$A$5:$A$29,0))/COUNTIF($H$5:$H$55,$H25),0) -> 9.61 | O25: К выполнению | P25: А-2 | Q25: Заглушка рассылки (А-2): записи в интерфейсе, демонстрируется на демоданных
A26: 22 | B26: OW-10 | C26: История | D26: Сотрудник ранчо, Владелец (Дасти) | E26: Справка «История жеребца» | F26: Как сотрудник ранчо, я хочу собрать историю жеребца (число случек за сезон, происшествия, записи о состоянии) не более чем за три перехода, чтобы показать её страховщику. | G26: Must | H26: 3.4 | I26: =IFERROR(INDEX('Пакеты ИСР'!$E$5:$E$29,MATCH($H26,'Пакеты ИСР'!$A$5:$A$29,0)),"") -> 3.1, 3.3, 2.5 | J26: Итерация 3 | K26: =IFERROR(INDEX('План итераций'!$C$5:$C$11,MATCH($J26,'План итераций'!$A$5:$A$11,0)),"") -> В3, 12.12.2026 | L26: 3 | M26: =IFERROR(INDEX('Пакеты ИСР'!$D$5:$D$29,MATCH($H26,'Пакеты ИСР'!$A$5:$A$29,0))/COUNTIF($H$5:$H$55,$H26),0) -> 27 | O26: К выполнению | P26: Т-03
A27: 23 | B27: OW-11 | C27: История | D27: Сотрудник ранчо, Владелец (Дасти) | E27: Справка «Перемещения и контакты» | F27: Как сотрудник ранчо, я хочу получить справку о перемещениях и контактах лошадей за период, чтобы при вспышке болезни за пять минут показать, какие лошади были на ранчо, откуда прибыли и с кем контактировали. | G27: Must | H27: 3.5 | I27: =IFERROR(INDEX('Пакеты ИСР'!$E$5:$E$29,MATCH($H27,'Пакеты ИСР'!$A$5:$A$29,0)),"") -> 3.2, 3.3, 2.5 | J27: Итерация 3 | K27: =IFERROR(INDEX('План итераций'!$C$5:$C$11,MATCH($J27,'План итераций'!$A$5:$A$11,0)),"") -> В3, 12.12.2026 | L27: 4 | M27: =IFERROR(INDEX('Пакеты ИСР'!$D$5:$D$29,MATCH($H27,'Пакеты ИСР'!$A$5:$A$29,0))/COUNTIF($H$5:$H$55,$H27),0) -> 28.83 | O27: К выполнению | P27: Т-04; А-7
A28: 24 | B28: OW-13 | C28: История | D28: Сотрудник ранчо, Владелец (Дасти) | E28: Проверить пару лошадей | F28: Как сотрудник ранчо, я хочу проверить пару лошадей на допустимость, чтобы не случить тех, кого нельзя. | G28: Must | H28: 4.2 | I28: =IFERROR(INDEX('Пакеты ИСР'!$E$5:$E$29,MATCH($H28,'Пакеты ИСР'!$A$5:$A$29,0)),"") -> 4.1, 3.1, 2.2 | J28: Итерация 4 | K28: =IFERROR(INDEX('План итераций'!$C$5:$C$11,MATCH($J28,'План итераций'!$A$5:$A$11,0)),"") -> В4, 26.12.2026 | L28: 7 | M28: =IFERROR(INDEX('Пакеты ИСР'!$D$5:$D$29,MATCH($H28,'Пакеты ИСР'!$A$5:$A$29,0))/COUNTIF($H$5:$H$55,$H28),0) -> 17.915 | O28: К выполнению | P28: Т-07 | Q28: Критерий 7: все пять недопустимых пар блокируются, три допустимые проходят
A29: 25 | B29: OW-14 | C29: История | D29: Сотрудник ранчо, Владелец (Дасти) | E29: Причина запрета пары | F29: Как сотрудник ранчо, я хочу видеть причину запрета (родство, занятость жеребца, неготовность кобылы), чтобы понимать, почему пара недопустима. | G29: Must | H29: 4.2 | I29: =IFERROR(INDEX('Пакеты ИСР'!$E$5:$E$29,MATCH($H29,'Пакеты ИСР'!$A$5:$A$29,0)),"") -> 4.1, 3.1, 2.2 | J29: Итерация 4 | K29: =IFERROR(INDEX('План итераций'!$C$5:$C$11,MATCH($J29,'План итераций'!$A$5:$A$11,0)),"") -> В4, 26.12.2026 | L29: 7 | M29: =IFERROR(INDEX('Пакеты ИСР'!$D$5:$D$29,MATCH($H29,'Пакеты ИСР'!$A$5:$A$29,0))/COUNTIF($H$5:$H$55,$H29),0) -> 17.915 | O29: К выполнению | P29: Т-07
A30: 26 | B30: CL-01 | C30: История | D30: Клиент | E30: Подать заявку на случку | F30: Как клиент, я хочу подать заявку на случку кобылы через систему, чтобы не звонить на ранчо. | G30: Should | H30: 5.1 | I30: =IFERROR(INDEX('Пакеты ИСР'!$E$5:$E$29,MATCH($H30,'Пакеты ИСР'!$A$5:$A$29,0)),"") -> 2.2, 2.3, 3.1 | J30: Итерация 4 | K30: =IFERROR(INDEX('План итераций'!$C$5:$C$11,MATCH($J30,'План итераций'!$A$5:$A$11,0)),"") -> В4, 26.12.2026 | L30: 8 | M30: =IFERROR(INDEX('Пакеты ИСР'!$D$5:$D$29,MATCH($H30,'Пакеты ИСР'!$A$5:$A$29,0))/COUNTIF($H$5:$H$55,$H30),0) -> 5.7783333 | O30: К выполнению | P30: Т-09
A31: 27 | B31: CL-02 | C31: История | D31: Клиент | E31: Указать кобылу, жеребца и период | F31: Как клиент, я хочу указать в заявке кобылу, жеребца и желаемый период, чтобы ранчо могло сразу проверить пару и назначить дату. | G31: Should | H31: 5.1 | I31: =IFERROR(INDEX('Пакеты ИСР'!$E$5:$E$29,MATCH($H31,'Пакеты ИСР'!$A$5:$A$29,0)),"") -> 2.2, 2.3, 3.1 | J31: Итерация 4 | K31: =IFERROR(INDEX('План итераций'!$C$5:$C$11,MATCH($J31,'План итераций'!$A$5:$A$11,0)),"") -> В4, 26.12.2026 | L31: 8 | M31: =IFERROR(INDEX('Пакеты ИСР'!$D$5:$D$29,MATCH($H31,'Пакеты ИСР'!$A$5:$A$29,0))/COUNTIF($H$5:$H$55,$H31),0) -> 5.7783333 | O31: К выполнению | P31: Т-09 | Q31: Вывод команды, подтвердить с заказчиком
A32: 28 | B32: OW-16 | C32: История | D32: Сотрудник ранчо, Владелец (Дасти) | E32: Входящие заявки клиентов | F32: Как сотрудник ранчо, я хочу видеть входящие заявки клиентов и их статусы, чтобы ни одна заявка не потерялась. | G32: Should | H32: 5.1 | I32: =IFERROR(INDEX('Пакеты ИСР'!$E$5:$E$29,MATCH($H32,'Пакеты ИСР'!$A$5:$A$29,0)),"") -> 2.2, 2.3, 3.1 | J32: Итерация 4 | K32: =IFERROR(INDEX('План итераций'!$C$5:$C$11,MATCH($J32,'План итераций'!$A$5:$A$11,0)),"") -> В4, 26.12.2026 | L32: 8 | M32: =IFERROR(INDEX('Пакеты ИСР'!$D$5:$D$29,MATCH($H32,'Пакеты ИСР'!$A$5:$A$29,0))/COUNTIF($H$5:$H$55,$H32),0) -> 5.7783333 | O32: К выполнению | P32: Т-09 | Q32: Вывод команды, подтвердить с заказчиком
A33: 29 | B33: OW-17 | C33: История | D33: Сотрудник ранчо, Владелец (Дасти) | E33: Принять или отклонить заявку | F33: Как сотрудник ранчо, я хочу принять или отклонить заявку после проверки пары, чтобы клиент получил ответ с причиной. | G33: Should | H33: 5.1 | I33: =IFERROR(INDEX('Пакеты ИСР'!$E$5:$E$29,MATCH($H33,'Пакеты ИСР'!$A$5:$A$29,0)),"") -> 2.2, 2.3, 3.1 | J33: Итерация 4 | K33: =IFERROR(INDEX('План итераций'!$C$5:$C$11,MATCH($J33,'План итераций'!$A$5:$A$11,0)),"") -> В4, 26.12.2026 | L33: 11 | M33: =IFERROR(INDEX('Пакеты ИСР'!$D$5:$D$29,MATCH($H33,'Пакеты ИСР'!$A$5:$A$29,0))/COUNTIF($H$5:$H$55,$H33),0) -> 5.7783333 | O33: К выполнению | P33: Т-09; Т-07 | Q33: Вывод команды, подтвердить с заказчиком
A34: 30 | B34: CL-05 | C34: История | D34: Клиент | E34: Видеть статус заявки | F34: Как клиент, я хочу видеть статус своей заявки, чтобы не уточнять его по телефону. | G34: Should | H34: 5.1 | I34: =IFERROR(INDEX('Пакеты ИСР'!$E$5:$E$29,MATCH($H34,'Пакеты ИСР'!$A$5:$A$29,0)),"") -> 2.2, 2.3, 3.1 | J34: Итерация 4 | K34: =IFERROR(INDEX('План итераций'!$C$5:$C$11,MATCH($J34,'План итераций'!$A$5:$A$11,0)),"") -> В4, 26.12.2026 | L34: 8 | M34: =IFERROR(INDEX('Пакеты ИСР'!$D$5:$D$29,MATCH($H34,'Пакеты ИСР'!$A$5:$A$29,0))/COUNTIF($H$5:$H$55,$H34),0) -> 5.7783333 | O34: К выполнению | P34: Т-09
A35: 31 | B35: CL-06 | C35: История | D35: Клиент | E35: Видеть историю заявок | F35: Как клиент, я хочу видеть историю своих заявок, чтобы знать, что и когда я заказывал. | G35: Should | H35: 5.1 | I35: =IFERROR(INDEX('Пакеты ИСР'!$E$5:$E$29,MATCH($H35,'Пакеты ИСР'!$A$5:$A$29,0)),"") -> 2.2, 2.3, 3.1 | J35: Итерация 4 | K35: =IFERROR(INDEX('План итераций'!$C$5:$C$11,MATCH($J35,'План итераций'!$A$5:$A$11,0)),"") -> В4, 26.12.2026 | L35: 8 | M35: =IFERROR(INDEX('Пакеты ИСР'!$D$5:$D$29,MATCH($H35,'Пакеты ИСР'!$A$5:$A$29,0))/COUNTIF($H$5:$H$55,$H35),0) -> 5.7783333 | O35: К выполнению | P35: Т-09
A36: 32 | B36: W-6.4 | C36: Работа по ИСР | D36: Команда | E36: Документация и приёмочные материалы | F36: Краткое руководство пользователя, приёмочные материалы, актуализация проектных документов. | G36: Must | H36: 6.4 | I36: =IFERROR(INDEX('Пакеты ИСР'!$E$5:$E$29,MATCH($H36,'Пакеты ИСР'!$A$5:$A$29,0)),"") -> 1.3, 6.3 | J36: Итерация 4 | K36: =IFERROR(INDEX('План итераций'!$C$5:$C$11,MATCH($J36,'План итераций'!$A$5:$A$11,0)),"") -> В4, 26.12.2026 | L36: 15 | M36: =IFERROR(INDEX('Пакеты ИСР'!$D$5:$D$29,MATCH($H36,'Пакеты ИСР'!$A$5:$A$29,0))/COUNTIF($H$5:$H$55,$H36),0) -> 18.67 | O36: К выполнению
A37: 33 | B37: W-6.2 | C37: Работа по ИСР | D37: Команда | E37: Тестирование и исправление дефектов | F37: Тестовые сценарии, проверка модулей каждой итерации по чек-листу, сквозной сценарий, исправления. | G37: Must | H37: 6.2 | I37: =IFERROR(INDEX('Пакеты ИСР'!$E$5:$E$29,MATCH($H37,'Пакеты ИСР'!$A$5:$A$29,0)),"") -> 3.1–5.3 по итерациям | J37: Сквозная работа | K37: =IFERROR(INDEX('План итераций'!$C$5:$C$11,MATCH($J37,'План итераций'!$A$5:$A$11,0)),"") -> каждая итерация | L37: 11, 14 | M37: =IFERROR(INDEX('Пакеты ИСР'!$D$5:$D$29,MATCH($H37,'Пакеты ИСР'!$A$5:$A$29,0))/COUNTIF($H$5:$H$55,$H37),0) -> 56.67 | O37: К выполнению | Q37: Идёт параллельно с началом работ по 3.1
A38: 34 | B38: W-6.3 | C38: Работа по ИСР | D38: Команда | E38: Демонстрации и приёмка | F38: Подготовка и проведение демонстраций В1–В4, фиксация замечаний в GitHub Issues, финальная приёмка. | G38: Must | H38: 6.3 | I38: =IFERROR(INDEX('Пакеты ИСР'!$E$5:$E$29,MATCH($H38,'Пакеты ИСР'!$A$5:$A$29,0)),"") -> 6.2 по итерациям | J38: Сквозная работа | K38: =IFERROR(INDEX('План итераций'!$C$5:$C$11,MATCH($J38,'План итераций'!$A$5:$A$11,0)),"") -> каждая итерация | L38: все | M38: =IFERROR(INDEX('Пакеты ИСР'!$D$5:$D$29,MATCH($H38,'Пакеты ИСР'!$A$5:$A$29,0))/COUNTIF($H$5:$H$55,$H38),0) -> 24.67 | O38: К выполнению | Q38: Демонстрации 14.11, 28.11, 12.12, 26.12
A39: 35 | B39: W-2.1 | C39: Работа по ИСР | D39: Команда | E39: Сбор и анализ требований (остаток) | F39: Уточнение требований и допущений по итогам демонстраций, подтверждение допущений с заказчиком. | G39: Must | H39: 2.1 | I39: =IFERROR(INDEX('Пакеты ИСР'!$E$5:$E$29,MATCH($H39,'Пакеты ИСР'!$A$5:$A$29,0)),"") -> 1.1 | J39: Сквозная работа | K39: =IFERROR(INDEX('План итераций'!$C$5:$C$11,MATCH($J39,'План итераций'!$A$5:$A$11,0)),"") -> каждая итерация | M39: =IFERROR(INDEX('Пакеты ИСР'!$D$5:$D$29,MATCH($H39,'Пакеты ИСР'!$A$5:$A$29,0))/COUNTIF($H$5:$H$55,$H39),0) -> 8.65 | O39: К выполнению
A40: 36 | B40: W-1.3 | C40: Работа по ИСР | D40: Команда | E40: Мониторинг и контроль | F40: Еженедельная синхронизация, учёт часов, освоенный объём, реестр рисков, журнал изменений, отчёт по итерации. | G40: Must | H40: 1.3 | I40: =IFERROR(INDEX('Пакеты ИСР'!$E$5:$E$29,MATCH($H40,'Пакеты ИСР'!$A$5:$A$29,0)),"") -> 1.2 | J40: Сквозная работа | K40: =IFERROR(INDEX('План итераций'!$C$5:$C$11,MATCH($J40,'План итераций'!$A$5:$A$11,0)),"") -> каждая итерация | L40: 15 | M40: =IFERROR(INDEX('Пакеты ИСР'!$D$5:$D$29,MATCH($H40,'Пакеты ИСР'!$A$5:$A$29,0))/COUNTIF($H$5:$H$55,$H40),0) -> 38.25 | O40: К выполнению
A41: 37 | B41: W-1.4 | C41: Работа по ИСР | D41: Команда | E41: Закрытие проекта | F41: Итоговый отчёт, архив документов, сравнение с уставом. | G41: Must | H41: 1.4 | I41: =IFERROR(INDEX('Пакеты ИСР'!$E$5:$E$29,MATCH($H41,'Пакеты ИСР'!$A$5:$A$29,0)),"") -> 1.3, 6.3 | J41: Сквозная работа | K41: =IFERROR(INDEX('План итераций'!$C$5:$C$11,MATCH($J41,'План итераций'!$A$5:$A$11,0)),"") -> каждая итерация | M41: =IFERROR(INDEX('Пакеты ИСР'!$D$5:$D$29,MATCH($H41,'Пакеты ИСР'!$A$5:$A$29,0))/COUNTIF($H$5:$H$55,$H41),0) -> 12.67 | O41: К выполнению | Q41: 28–31.12.2026, после В4
...

Sheet План итераций
A1: План итераций
A2: Даты вех — по уставу (п. 3.1). Результат каждой итерации сформулирован как то, что показывается заказчику на демонстрации. Счётчики и часы считаются по листу «Бэклог продукта».
A4: Итерация | B4: Период | C4: Веха и дата | D4: Результат для показа заказчику | E4: Критерии приёмки (п. 2.4) | F4: Позиций | G4: из них историй | H4: Остаток трудоёмкости, ч | I4: Что не входит
A5: Нулевой спринт | B5: 19.10–31.10.2026 | C5: Фаза 4, 31.10.2026 | D5: Готовы story map, бэклог продукта и план итерации 1; развёрнуты репозиторий, трекер, Figma и каркас приложения на демонстрационном стенде; описаны архитектура и модель данных; готов дизайн экранов; работает вход с выбором роли. | E5: — | F5: =COUNTIF('Бэклог продукта'!$J$5:$J$55,A5) -> 7 | G5: =COUNTIFS('Бэклог продукта'!$J$5:$J$55,A5,'Бэклог продукта'!$C$5:$C$55,"*история") -> 3 | H5: =SUMIF('Бэклог продукта'!$J$5:$J$55,A5,'Бэклог продукта'!$M$5:$M$55) -> 96.57 | I5: Демонстрация заказчику не проводится
A6: Итерация 1 | B6: 02.11–14.11.2026 | C6: В1, 14.11.2026 | D6: Реестр лошадей трёх категорий с карточкой и родословной на демонстрационных данных (не менее 15 лошадей), добавление лошади; согласованный образец стиля; утверждена таблица правил совместимости. | E6: 1, 12, 14 (часть) | F6: =COUNTIF('Бэклог продукта'!$J$5:$J$55,A6) -> 5 | G6: =COUNTIFS('Бэклог продукта'!$J$5:$J$55,A6,'Бэклог продукта'!$C$5:$C$55,"*история") -> 5 | H6: =SUMIF('Бэклог продукта'!$J$5:$J$55,A6,'Бэклог продукта'!$M$5:$M$55) -> 83.67 | I6: Размещение и перемещения (перенесены на итерацию 2)
A7: Итерация 2 | B7: 16.11–28.11.2026 | C7: В2, 28.11.2026 | D7: Размещение и перемещения лошадей (не менее 25 записей, 4 мест, 5 мест происхождения); простая форма записей о готовности кобылы, травмах и состоянии; комплект заглушек пяти внешних сервисов. | E7: 2, 6, 13 | F7: =COUNTIF('Бэклог продукта'!$J$5:$J$55,A7) -> 9 | G7: =COUNTIFS('Бэклог продукта'!$J$5:$J$55,A7,'Бэклог продукта'!$C$5:$C$55,"*история") -> 9 | H7: =SUMIF('Бэклог продукта'!$J$5:$J$55,A7,'Бэклог продукта'!$M$5:$M$55) -> 80.5 | I7: Справки (перенесены на итерацию 3)
A8: Итерация 3 | B8: 30.11–12.12.2026 | C8: В3, 12.12.2026 | D8: Справки «История жеребца» и «Перемещения и контакты»: каждая не более чем за три перехода и за пять минут; выгрузка справок заглушкой. | E8: 3, 4, 5 | F8: =COUNTIF('Бэклог продукта'!$J$5:$J$55,A8) -> 2 | G8: =COUNTIFS('Бэклог продукта'!$J$5:$J$55,A8,'Бэклог продукта'!$C$5:$C$55,"*история") -> 2 | H8: =SUMIF('Бэклог продукта'!$J$5:$J$55,A8,'Бэклог продукта'!$M$5:$M$55) -> 55.83 | I8: Проверка совместимости и кабинет клиента (итерация 4)
A9: Итерация 4 | B9: 14.12–26.12.2026 | C9: В4, 26.12.2026 | D9: Проверка совместимости пар с причиной запрета; кабинет клиента: заявка, статус и история; приём или отклонение заявки; сквозной сценарий двух ролей (заявка, проверка совместимости, реестр); руководство пользователя; финальная приёмка по чек-листу. | E9: 7, 8 (уточнён), 11 (уточнён), 15 | F9: =COUNTIF('Бэклог продукта'!$J$5:$J$55,A9) -> 9 | G9: =COUNTIFS('Бэклог продукта'!$J$5:$J$55,A9,'Бэклог продукта'!$C$5:$C$55,"*история") -> 8 | H9: =SUMIF('Бэклог продукта'!$J$5:$J$55,A9,'Бэклог продукта'!$M$5:$M$55) -> 89.17 | I9: Очередь, календарь, заказ семени, счета, отчёты (исключены)
A10: Сквозная работа | B10: весь проект | C10: каждая итерация | D10: Мониторинг и контроль, тестирование, подготовка демонстраций, уточнение требований, закрытие проекта (28–31.12). | E10: 11, 14, 15 | F10: =COUNTIF('Бэклог продукта'!$J$5:$J$55,A10) -> 5 | G10: =COUNTIFS('Бэклог продукта'!$J$5:$J$55,A10,'Бэклог продукта'!$C$5:$C$55,"*история") -> 0 | H10: =SUMIF('Бэклог продукта'!$J$5:$J$55,A10,'Бэклог продукта'!$M$5:$M$55) -> 140.91 | I10: —
A11: Вне базового плана | B11: — | C11: — | D11: 14 историй из пакетов 4.3, 5.2, 5.3 и 5.4 (очередь и календарь, заказ семени, счета и платежи, отчёты). Возврат в план возможен только по запросу на изменение. | E11: 9, 10, 16 сняты | F11: =COUNTIF('Бэклог продукта'!$J$5:$J$55,A11) -> 14 | G11: =COUNTIFS('Бэклог продукта'!$J$5:$J$55,A11,'Бэклог продукта'!$C$5:$C$55,"*история") -> 14 | H11: =SUMIF('Бэклог продукта'!$J$5:$J$55,A11,'Бэклог продукта'!$M$5:$M$55) -> 0 | I11: —
A12: Итого | F12: =SUM(F5:F11) -> 51 | G12: =SUM(G5:G11) -> 41 | H12: =SUM(H5:H11) -> 546.65
A13: Проверка: позиций в бэклоге | F13: =COUNTA('Бэклог продукта'!$B$5:$B$55) -> 51
A14: Проверка: остаток по расписанию v1.0, ч | H14: ='Пакеты ИСР'!D30 -> 546.65

Sheet Пакеты ИСР
A1: Справочник пакетов ИСР для бэклога
A2: Остаток трудоёмкости взят из расписания v1.0 (лист «Ресурсы», работы с 19.10.2026); у исключённых пакетов 0. Предшественники и приоритеты — из сводной таблицы оценок. Синим выделены исходные данные.
A4: № | B4: Пакет работ | C4: Приоритет | D4: Остаток трудоёмкости, ч | E4: Предшественники | F4: Вариант Б | G4: Позиций в бэклоге
A5: 1.1 | B5: Инициация проекта | C5: Must | D5: 0 | E5: — | F5: в плане | G5: =COUNTIF('Бэклог продукта'!$H$5:$H$55,A5) -> 1
A6: 1.2 | B6: Планирование проекта | C6: Must | D6: 13.07 | E6: 1.1 | F6: в плане | G6: =COUNTIF('Бэклог продукта'!$H$5:$H$55,A6) -> 1
A7: 1.3 | B7: Мониторинг и контроль | C7: Must | D7: 38.25 | E7: 1.2 | F7: в плане | G7: =COUNTIF('Бэклог продукта'!$H$5:$H$55,A7) -> 1
A8: 1.4 | B8: Закрытие проекта | C8: Must | D8: 12.67 | E8: 1.3, 6.3 | F8: в плане | G8: =COUNTIF('Бэклог продукта'!$H$5:$H$55,A8) -> 1
A9: 2.1 | B9: Сбор и анализ требований | C9: Must | D9: 8.65 | E9: 1.1 | F9: в плане | G9: =COUNTIF('Бэклог продукта'!$H$5:$H$55,A9) -> 1
A10: 2.2 | B10: Проектирование архитектуры и базы данных | C10: Must | D10: 31 | E10: 2.1 | F10: в плане | G10: =COUNTIF('Бэклог продукта'!$H$5:$H$55,A10) -> 1
A11: 2.3 | B11: Проектирование пользовательского интерфейса | C11: Must | D11: 35.83 | E11: 2.1, 2.2 | F11: в плане | G11: =COUNTIF('Бэклог продукта'!$H$5:$H$55,A11) -> 2
A12: 2.4 | B12: Подготовка среды и инструментов | C12: Must | D12: 16.67 | E12: 1.2 | F12: в плане | G12: =COUNTIF('Бэклог продукта'!$H$5:$H$55,A12) -> 2
A13: 2.5 | B13: Подготовка демонстрационных данных | C13: Must | D13: 22.67 | E13: 2.2, 2.4 | F13: в плане | G13: =COUNTIF('Бэклог продукта'!$H$5:$H$55,A13) -> 1
A14: 3.1 | B14: Реестр лошадей и карточка лошади | C14: Must | D14: 46.33 | E14: 2.2, 2.3, 2.4, 2.5 | F14: в плане | G14: =COUNTIF('Бэклог продукта'!$H$5:$H$55,A14) -> 3
A15: 3.2 | B15: Размещение и перемещения | C15: Must | D15: 31 | E15: 3.1 | F15: в плане | G15: =COUNTIF('Бэклог продукта'!$H$5:$H$55,A15) -> 3
A16: 3.3 | B16: Ввод записей о состоянии и происшествиях | C16: Must | D16: 20.67 | E16: 3.1, 2.3 | F16: в плане | G16: =COUNTIF('Бэклог продукта'!$H$5:$H$55,A16) -> 3
... A29: 6.4 | B29: Документация и приёмочные материалы | C29: Must | D29: 18.67 | E29: 1.3, 6.3 | F29: в плане | G29: =COUNTIF('Бэклог продукта'!$H$5:$H$55,A29) -> 1
B30: Итого | D30: =SUM(D5:D29) -> 546.65 | G30: =SUM(G5:G29) -> 51

Sheet Пояснения
A1: Бэклог продукта: пояснения
A2: 1. Из чего состоит бэклог
A3: 51 позиция: 41 история с карты историй (в том числе 5 обеспечивающих) и 10 работ из ИСР, которые не создают функций для пользователя (1.1–1.4, 2.1, 2.2, 2.4, 6.2–6.4). Благодаря этому в бэклоге присутствуют все 25 пакетов ИСР, а освоенный объём считается по одной схеме.
A4: 2. Как расставлены приоритеты и порядок
A5: Приоритет MoSCoW берётся из устава и сводной таблицы оценок. Порядок строк определяют итерация по базовому плану, затем приоритет, затем зависимости. Таблица правил совместимости (OW-15) стоит первой в итерации 1: её даёт заказчик, срок 14.11.2026 (А-9, риск Р2).
A6: 3. Как нарезаны итерации
A7: Базовым планом считается расписание v1.0 (вариант Б): пересчёт не делался, заказчик утверждает план как есть. Пакеты 4.3, 5.2, 5.3 и 5.4 исключены, их 14 историй оставлены внизу бэклога со статусом «Вне базового плана». Критерии приёмки 9, 10 и 16 сняты, критерии 8 и 11 уточнены (без заказа семени и счетов).
A8: Часы в бэклоге — ориентир: остаток трудоёмкости пакета по расписанию, поделённый поровну между позициями этого пакета. После покера планирования веса заменяются долями по story points, и освоенный объём считается уже по ним.
A9: 4. На что обратить внимание
A10: а) Все три истории пакета 6.1 стоят в итерации 2, потому что расписание завершает этот пакет к В2. Кнопка выгрузки справок (OW-12) подключается к самим справкам в итерации 3.
A11: б) В итерации 4 собраны проверка совместимости, кабинет клиента, руководство и финальная приёмка. Это самая нагруженная итерация, поэтому при отставании раньше всего пострадают истории Should пакета 5.1 (OW-16, OW-17, CL-05, CL-06), но не Must пакета 4.2.
A12: в) Пять историй (CL-02, OW-03, OW-16, OW-17, FN-05) выведены командой, их нужно подтвердить с заказчиком. FN-05 в плане не участвует.
A13: г) Статусы указаны по умолчанию («К выполнению»); фактическое состояние работ нулевого спринта нужно обновить в трекере.
